Workbook

Sheet README
A1: README
D3: 모델 구조 · 시트 구성 · 검토 가이드
D4: 기준 시나리오: 개발 PF → 2029년 리파이낸싱 → 무신사 10년 마스터리스 → 매각
C5: X | D5: 01 | 요약 및 현금흐름 / CoC
D6: 핵심 수익률과 전체 현금흐름 구조를 요약
E7: 가정 (Assumptions) | H7: 운영·금융·개발·매각 관련 주요 가정을 설정하는 시트
E8: 운영 현금흐름 (Operating CF) | H8: 연도별 NOI, 이자비용, 에쿼티 현금흐름 및 매각대금을 산출
E9: 개발 PF (Dev PF) | H9: 개발기간 PF 인출, 자본화 이자 및 리파이낸싱 구조를 산출
E10: 매각 및 리스크 분석 (Exit & Risk Analysis) | H10: 기준·하방·스트레스 시나리오, 매각 Cap Rate 민감도, 임대차 만기 및 리파이낸싱 리스크 분석
C12: X | D12: 02 | 주요 가정 근거
D13: 핵심 모델링 가정과 가치평가 근거를 정리
E14: 총사업비 (Total Development Cost) | H14: 토지비·공사비·금융비용 등을 반영한 총사업비 산출 근거
E15: 매각가치 근거 (Exit Value Reason) | H15: 비교 거래사례와 시장 데이터를 활용한 매각 Cap Rate 및 매각가치 적정성 검토
C17: X | D17: 03 | 임대료 / NOI 산출
D18: 모델에 적용된 임대료 및 NOI 가정의 시장 근거를 단계별로 검토
E19: 임대료 요약 (임대료 Summary) | H19: 오피스 / 리테일 최종 적용 임대료와 연간 임대수익을 요약
E20: 산정 방법론 (Methodology) | H20: 비교사례 정규화, 벤치마킹 및 목표 임대료 산정 방법론
E21: 비교사례 (Peer Comps) | H21: 시장 임대료 벤치마킹에 활용한 비교사례 데이터
E22: 목표 임대료 (Target Rent) | H22: 용도·층별 비교사례를 바탕으로 최종 적용 임대료를 선정
E23: 원천 데이터 >>> | H23: 임대료 산정에 활용한 원천 데이터 및 보조자료 구간
C25: X | D25: 04 | 모델 표기 규칙
D26: 재무모델 전반에 적용된 색상 및 표기 기준
E27: 직접 입력값 | H27: 파란색 글씨 — 사용자가 직접 변경하는 가정 및 시나리오 입력값
E28: 수식 | H28: 검정색 글씨 — 동일 시트 내 계산식 및 산출값
E29: 시트 간 연결 | H29: 초록색 글씨 — 다른 시트의 값을 참조하는 연결 수식
E30: 핵심 가정 / 결과 | H30: 노란색 음영 — 검토자가 우선 확인해야 하는 주요 가정 또는 핵심 결과
E31: 단위 | H31: 각 시트 상단 표기 기준을 따름 (예: 억원 / 만원 / 평 / %)
C33: X | D33: 05 | 권장 검토 순서
D34: 투자심사 또는 공모전 검토 시 권장하는 모델 확인 순서
E35: 1. 요약 (Summary) | H35: 핵심 수익률, 자본구조, 현금흐름 구조 및 주요 결과를 우선 확인
E36: 2. 매각 및 리스크 분석 | H36: 기준 시나리오와 함께 하방·스트레스 시나리오 및 민감도 결과를 검토
E37: 3. 주요 가정 | H37: 임대료, 금융조건, 매각 Cap Rate, 매각비용, 일정 및 운영가정을 확인
E38: 4. 근거자료 시트 | H38: 총사업비, 매각가치 및 임대료 가정이 근거자료와 일치하는지 검증
D40: 검토 유의사항 | F40: 기준 시나리오 수익률은 반드시 '매각 및 리스크 분석(Exit & Risk Analysis)'의 하방·스트레스 분석과 함께 검토해야 하며, 특히 매각 Cap Rate, 임대차 만기, 공사비 증가 및 리파이낸싱 가정에 민감합니다.

Sheet Summary
A1: E4 Development – Equity Return Summary
D3: Base Case: Development PF → 2029 Refi → 10Y MUSINSA Master Lease → Exit
D5: Total Development Cost | E5: =Assumptions!F5 -> 1073 | F5: Y1 NOI | G5: =Assumptions!F18 -> 78.400817 | H5: Gross Exit Value | I5: ='Operating CF'!O20 -> 2341.4254 | J5: All-in Equity XIRR | K5: ='Operating CF'!E35 -> 0.15724347
D6: Equity | E6: =Assumptions!F10 -> 450 | F6: Y1 Yield on Cost | G6: =G5/E5 -> 0.073066931 | H6: Net Equity Exit Proceeds | I6: ='Operating CF'!O23 -> 1695.0111 | J6: Development PF Interest | K6: ='Dev PF'!E24 -> 56.325777
D7: Development PF | E7: =Assumptions!F11 -> 623 | F7: Stabilized Debt Rate | G7: =Assumptions!F21 -> 0.0475 | H7: Equity MOIC | I7: ='Operating CF'!E37 -> 5.1063636 | J7: Y10 CoC | K7: ='Operating CF'!O16 -> 0.16156174
D8: Equity / Cost | E8: =E6/E5 -> 0.4193849 | F8: Y1 CoC | G8: ='Operating CF'!F16 -> 0.10846293 | H8: Post-completion IRR | I8: ='Operating CF'!E36 -> 0.22100128 | J8: Exit Cap Rate | K8: =Assumptions!F23 -> 0.045
C11: X | D11: KEY CASH FLOW LOGIC
D12: Step | E12: Cash Flow | F12: Base Case | G12: Comment
D13: 1. Development | E13: Equity Contribution | F13: (450.0) | G13: 2026-10 land acquisition; 450억원 equity contribution
D14: 2. Development | E14: Senior PF | F14: 623.0 | G14: 5.75%, drawn over development; interest capitalized
D15: 3. Stabilization | E15: Refinance | F15: 623.0 | G15: 4.75%, interest-only; development PF repaid
D16: 4. Operation | E16: Y1 CF to Equity | F16: 48.8 | G16: NOI 78.4 less annual interest 29.6
D17: 5. Exit | E17: Gross / Net Equity Exit | F17: 2,341.4 / 1,695.0 | G17: Y11 forward NOI ÷ 4.50% cap; 1.0% sale cost; repay 623 debt
C20: X | D20: IMPORTANT RETURN RECONCILIATION
D21: 준공 이후 IRR은 22.1%
D22: 450억원의 자기자본은 2026년 토지 매입 시점에 투입되고, 현금배당은 2029년 준공 이후부터 시작되므로, 개발기간부터 Exit까지 전체 기간을 반영한 XIRR은 15.7%로 낮아짐.
D23: 기존 무신사에서 제공한 임대료 예시가 아닌 자체 임대료 산출로 NOI 추정
D24: Exit / risk downside framework → see 'Exit & Risk Analysis' tab
C26: X | D26: OPERATING CASH-ON-CASH PROFILE
D27: Metric | E27: Y1 | F27: Y2 | G27: Y3 | H27: Y4 | I27: Y5 | J27: Y6 | K27: Y10
D28: CoC | E28: ='Operating CF'!F16 -> 0.10846293 | F28: ='Operating CF'!G16 -> 0.11368965 | G28: ='Operating CF'!H16 -> 0.11907317 | H28: ='Operating CF'!I16 -> 0.1246182 | I28: ='Operating CF'!J16 -> 0.13032958 | J28: ='Operating CF'!K16 -> 0.1362123 | K28: ='Operating CF'!O16 -> 0.16156174
D29: CF to Equity | E29: ='Operating CF'!F15 -> 48.808317 | F29: ='Operating CF'!G15 -> 51.160342 | G29: ='Operating CF'!H15 -> 53.582927 | H29: ='Operating CF'!I15 -> 56.07819 | I29: ='Operating CF'!J15 -> 58.64831 | J29: ='Operating CF'!K15 -> 61.295535 | K29: ='Operating CF'!O15 -> 72.702784

Sheet CF & CoC >>>

Sheet Assumptions
A1: E4 Development – Model Assumptions
C3: X | D3: DEVELOPMENT COST & CAPITAL STRUCTURE
D4: Assumption | F4: Value | G4: Unit | H4: Source / Rationale | I4: Editable?
D5: Total Development Cost | E5: 총 사업비 | F5: 1073 | G5: 억원 | H5: User-updated input: Total Development Cost = 1,073억원 | I5: Yes
D6: Land | E6: 토지비 | F6: 580 | G6: 억원 | H6: User-provided E4 deck | I6: Yes
D7: Construction | E7: 공사비 | F7: 312.5 | G7: 억원 | H7: User-provided E4 deck | I7: Yes
D8: Design / TI / Tax / Contingency | E8: 설계비 / TI / 세금 / 예비비 | F8: 116.4 | G8: 억원 | H8: User-provided E4 deck | I8: Yes
D9: Financing & Other | E9: 금융비용 및 기타비용 | F9: 64.1 | G9: 억원 | H9: Plug to reconcile updated TDC; equals financing fee + capitalized PF interest | I9: Yes
D10: Total Equity | E10: 총 자기자본 | F10: 450 | G10: 억원 | H10: User-provided E4 deck | I10: Yes
D11: Senior Development PF Facility | E11: 선순위 개발 PF 대출 | F11: 623 | G11: 억원 | H11: Assumed +5억원 incremental PF to fund updated TDC while keeping equity at 450억원 | I11: Yes
D12: Initial Land PF | E12: 초기 토지 PF 대출 | F12: 130 | G12: 억원 | H12: User-provided funding sequence | I12: Yes
D13: Development PF Rate | E13: 개발 PF 금리 | F13: 0.0575 | G13: % | H13: Illustrative: ~100bp premium to stabilized office senior debt | I13: Yes
D14: Development Financing Fee | E14: 개발금융 수수료 | F14: 7.7742228 | G14: 억원 | H14: Solved so Financing & Other reconciles to 64.1억원 at 5.75% PF rate | I14: Yes
C16: X | D16: STABILIZED OPERATING / EXIT ASSUMPTIONS
D17: Assumption | F17: Value | G17: Unit | H17: Source / Rationale | I17: Editable?
D18: Y1 Base Rental NOI | E18: 1년차 기본 임대 NOI | F18: ='임대료 Summary'!E6/10000 -> 78.400817 | G18: 억원 | H18: User-updated input: 784,008만원 annual NOI = 78.4008억원 | I18: Yes
D19: Annual NOI Growth | E19: 연간 NOI 성장률 | F19: 0.03 | G19: % | H19: 3.0% contractual annual escalation | I19: Yes
D20: Stabilized Senior Loan | E20: 안정화 후 선순위 대출 | F20: 623 | G20: 억원 | H20: Assume full refinance of updated development PF at completion | I20: Yes
D21: Stabilized Loan Rate | E21: 안정화 후 대출 금리 | F21: 0.0475 | G21: % | H21: Illustrative base case; 2026 office senior debt near ~5% all-in | I21: Yes
D22: Principal Amortization | E22: 원금 상환 | F22: 0 | G22: % | H22: Interest-only base case; bullet repayment at exit | I22: Yes
D23: Exit Cap Rate | E23: 매각 Cap Rate | F23: 0.045 | G23: % | H23: Base case; Y11 forward NOI / cap rate | I23: Yes
D24: Sale Cost | E24: 매각 비용 | F24: 0.01 | G24: % | H24: Illustrative transaction cost assumption | I24: Yes
D25: Lease Term | E25: 임대차 기간 | F25: 10 | G25: years | H25: MUSINSA 10Y master lease | I25: Yes
D26: Land / Equity Close Date | E26: 토지 매입 / Equity 납입일 | F26: 46296 | G26: date | H26: Project schedule assumption | I26: Yes
D27: Lease Commencement / Completion | E27: 임대 개시일 / 준공일 | F27: 47300 | G27: date | H27: 2029.07 completion assumption | I27: Yes
C29: X | D29: MARKET REFERENCE LINKS
D30: Topic | F30: Model Use | G30: Reference | H30: URL
D31: 2026 PF market | E31: 2026년 PF 시장 | F31: Context only | G31: FSC PF market monitoring, July 2026 | H31: https://www.fsc.go.kr/po010101/87252
D32: Office senior debt | E32: 오피스 선순위 대출 | F32: Stabilized debt anchor | G32: SeoulPI: prime office senior debt near 5.0% all-in, Jun 2026 | H32: https://seoulpi.io/article/00566835848106491904
D33: Office senior debt history | E33: 오피스 선순위 대출 추이 | F33: Cross-check | G33: SeoulPI: Seoul office senior loan rates 3% high to 4% range, Jun 2025 | H33: https://seoulpi.io/article/00436311156690305024

Sheet Operating CF
C1: X | D1: Stabilized Operating Cash Flow & Exit (억원)
D3: Operating Year | F3: Y1 | G3: Y2 | H3: Y3 | I3: Y4 | J3: Y5 | K3: Y6 | L3: Y7 | M3: Y8 | N3: Y9 | O3: Y10
D4: Distribution Date | F4: 47665 | G4: 48030 | H4: 48396 | I4: 48761 | J4: 49126 | K4: 49491 | L4: 49857 | M4: 50222 | N4: 50587 | O4: 50952
D6: NOI | F6: =Assumptions!$F$18 -> 78.400817 | G6: =F6*(1+Assumptions!$F$19) -> 80.752842 | H6: =G6*(1+Assumptions!$F$19) -> 83.175427 | I6: =H6*(1+Assumptions!$F$19) -> 85.67069 | J6: =I6*(1+Assumptions!$F$19) -> 88.24081 | K6: =J6*(1+Assumptions!$F$19) -> 90.888035 | L6: =K6*(1+Assumptions!$F$19) -> 93.614676 | M6: =L6*(1+Assumptions!$F$19) -> 96.423116 | N6: =M6*(1+Assumptions!$F$19) -> 99.31581 | O6: =N6*(1+Assumptions!$F$19) -> 102.29528
D7: NOI Growth | F7: 0 | G7: =G6/F6-1 -> 0.03 | H7: =H6/G6-1 -> 0.03 | I7: =I6/H6-1 -> 0.03 | J7: =J6/I6-1 -> 0.03 | K7: =K6/J6-1 -> 0.03 | L7: =L6/K6-1 -> 0.03 | M7: =M6/L6-1 -> 0.03 | N7: =N6/M6-1 -> 0.03 | O7: =O6/N6-1 -> 0.03
D9: Beginning Senior Loan | F9: =Assumptions!$F$20 -> 623 | G9: =F13 -> 623 | H9: =G13 -> 623 | I9: =H13 -> 623 | J9: =I13 -> 623 | K9: =J13 -> 623 | L9: =K13 -> 623 | M9: =L13 -> 623 | N9: =M13 -> 623 | O9: =N13 -> 623
D10: Cash Interest Rate | F10: =Assumptions!$F$21 -> 0.0475 | G10: =Assumptions!$F$21 -> 0.0475 | H10: =Assumptions!$F$21 -> 0.0475 | I10: =Assumptions!$F$21 -> 0.0475 | J10: =Assumptions!$F$21 -> 0.0475 | K10: =Assumptions!$F$21 -> 0.0475 | L10: =Assumptions!$F$21 -> 0.0475 | M10: =Assumptions!$F$21 -> 0.0475 | ... O10: =Assumptions!$F$21 -> 0.0475
D11: Cash Interest | F11: =F9*F10 -> 29.5925 | G11: =G9*G10 -> 29.5925 | H11: =H9*H10 -> 29.5925 | I11: =I9*I10 -> 29.5925 | J11: =J9*J10 -> 29.5925 | K11: =K9*K10 -> 29.5925 | L11: =L9*L10 -> 29.5925 | M11: =M9*M10 -> 29.5925 | ... O11: =O9*O10 -> 29.5925
D12: Principal Amortization | F12: =F9*Assumptions!$F$22 -> 0 | G12: =G9*Assumptions!$F$22 -> 0 | H12: =H9*Assumptions!$F$22 -> 0 | I12: =I9*Assumptions!$F$22 -> 0 | J12: =J9*Assumptions!$F$22 -> 0 | K12: =K9*Assumptions!$F$22 -> 0 | L12: =L9*Assumptions!$F$22 -> 0 | M12: =M9*Assumptions!$F$22 -> 0 | ... O12: =O9*Assumptions!$F$22 -> 0
D13: Ending Senior Loan | F13: =F9-F12 -> 623 | G13: =G9-G12 -> 623 | H13: =H9-H12 -> 623 | I13: =I9-I12 -> 623 | J13: =J9-J12 -> 623 | K13: =K9-K12 -> 623 | L13: =L9-L12 -> 623 | M13: =M9-M12 -> 623 | ... O13: =O9-O12 -> 623
D15: Cash Flow to Equity (Pre-Sale) | F15: =F6-F11-F12 -> 48.808317 | G15: =G6-G11-G12 -> 51.160342 | H15: =H6-H11-H12 -> 53.582927 | I15: =I6-I11-I12 -> 56.07819 | J15: =J6-J11-J12 -> 58.64831 | K15: =K6-K11-K12 -> 61.295535 | L15: =L6-L11-L12 -> 64.022176 | M15: =M6-M11-M12 -> 66.830616 | ... O15: =O6-O11-O12 -> 72.702784
D16: Cash-on-Cash | F16: =F15/Assumptions!$F$10 -> 0.10846293 | G16: =G15/Assumptions!$F$10 -> 0.11368965 | H16: =H15/Assumptions!$F$10 -> 0.11907317 | I16: =I15/Assumptions!$F$10 -> 0.1246182 | J16: =J15/Assumptions!$F$10 -> 0.13032958 | K16: =K15/Assumptions!$F$10 -> 0.1362123 | L16: =L15/Assumptions!$F$10 -> 0.1422715 | M16: =M15/Assumptions!$F$10 -> 0.14851248 | ... O16: =O15/Assumptions!$F$10 -> 0.16156174
D18: Forward NOI | F18: 0 | G18: 0 | H18: 0 | I18: 0 | J18: 0 | K18: 0 | L18: 0 | M18: 0 | N18: 0 | O18: =O6*(1+Assumptions!$F$19) -> 105.36414
D19: Exit Cap Rate | F19: 0 | G19: 0 | H19: 0 | I19: 0 | J19: 0 | K19: 0 | L19: 0 | M19: 0 | N19: 0 | O19: =Assumptions!$F$23 -> 0.045
D20: Gross Exit Value | F20: 0 | G20: 0 | H20: 0 | I20: 0 | J20: 0 | K20: 0 | L20: 0 | M20: 0 | N20: 0 | O20: =O18/O19 -> 2341.4254
D21: Sale Cost | F21: 0 | G21: 0 | H21: 0 | I21: 0 | J21: 0 | K21: 0 | L21: 0 | M21: 0 | N21: 0 | O21: =O20*Assumptions!$F$24 -> 23.414254
D22: Debt Repayment at Exit | F22: 0 | G22: 0 | H22: 0 | I22: 0 | J22: 0 | K22: 0 | L22: 0 | M22: 0 | N22: 0 | O22: =O13 -> 623
D23: Net Sale Proceeds | F23: 0 | G23: 0 | H23: 0 | I23: 0 | J23: 0 | K23: 0 | L23: 0 | M23: 0 | N23: 0 | O23: =O20-O21-O22 -> 1695.0111
D25: Total Equity Cash Flow | F25: =F15+F23 -> 48.808317 | G25: =G15+G23 -> 51.160342 | H25: =H15+H23 -> 53.582927 | I25: =I15+I23 -> 56.07819 | J25: =J15+J23 -> 58.64831 | K25: =K15+K23 -> 61.295535 | L25: =L15+L23 -> 64.022176 | M25: =M15+M23 -> 66.830616 | ... O25: =O15+O23 -> 1767.7139
C28: X | D28: EQUITY RETURN BRIDGE
D29: Metric | E29: Initial Equity | F29: Y1 | G29: Y2 | H29: Y3 | I29: Y4 | J29: Y5 | K29: Y6 | L29: Y7 | M29: Y8 | N29: Y9 | O29: Y10
D30: Date | E30: =Assumptions!$F$26 -> 46296 | F30: =F4 -> 47665 | G30: =G4 -> 48030 | H30: =H4 -> 48396 | I30: =I4 -> 48761 | J30: =J4 -> 49126 | K30: =K4 -> 49491 | L30: =L4 -> 49857 | M30: =M4 -> 50222 | ... O30: =O4 -> 50952
D31: Equity CF | E31: =-Assumptions!$F$10 -> -450 | F31: =F25 -> 48.808317 | G31: =G25 -> 51.160342 | H31: =H25 -> 53.582927 | I31: =I25 -> 56.07819 | J31: =J25 -> 58.64831 | K31: =K25 -> 61.295535 | L31: =L25 -> 64.022176 | M31: =M25 -> 66.830616 | ... O31: =O25 -> 1767.7139
D32: Operating-period CF | E32: =-Assumptions!$F$10 -> -450 | F32: =F25 -> 48.808317 | G32: =G25 -> 51.160342 | H32: =H25 -> 53.582927 | I32: =I25 -> 56.07819 | J32: =J25 -> 58.64831 | K32: =K25 -> 61.295535 | L32: =L25 -> 64.022176 | M32: =M25 -> 66.830616 | ... O32: =O25 -> 1767.7139
D34: Return Metric | E34: Value
D35: All-in Equity XIRR (incl. development) | E35: =XIRR(E31:O31,E30:O30) -> 0.15724347
D36: Post-completion Equity IRR | E36: =IRR(E32:O32) -> 0.22100128
D37: Equity MOIC | E37: =SUM(F31:O31)/ABS(E31) -> 5.1063636
D38: Y1 / Y10 CoC | E38: =TEXT(F16,"0.0%")&" / "&TEXT(O16,"0.0%") -> 10.8% / 16.2%

Sheet Exit & Risk Analysis
A1: Exit & Risk Analysis
D2: 0 | R2: =Assumptions!$F$26 -> 46296 | S2: ='Operating CF'!F$4 -> 47665 | T2: ='Operating CF'!G$4 -> 48030 | U2: ='Operating CF'!H$4 -> 48396 | V2: ='Operating CF'!I$4 -> 48761 | W2: ='Operating CF'!J$4 -> 49126 | X2: ='Operating CF'!K$4 -> 49491 | Y2: ='Operating CF'!L$4 -> 49857 | Z2: ='Operating CF'!M$4 -> 50222 | ... AB2: ='Operating CF'!O$4 -> 50952
D3: Summary
D4: 보수적인 레버리지 구조를 기반으로 Base Case에서 15.7%의 All-in XIRR을 확보
D5: Downside / Stress에서도 11.4% / 7.6%의 수익률을 유지
D6: 다만 Exit 수익 의존도가 높고 임대차 만기와 Exit 시점이 중첩되는 만큼, 조기 재계약 또는 만기 이전 Exit 전략이 핵심 리스크 관리 요소
D8: 임대차 갱신, Exit Valuation, 공사비 및 리파이낸싱 리스크를 반영한 Base / Downside / Stress 시나리오 분석 | R8: =-Assumptions!$F$10 -> -450 | S8: ='Operating CF'!F$15 -> 48.808317 | T8: ='Operating CF'!G$15 -> 51.160342 | U8: ='Operating CF'!H$15 -> 53.582927 | V8: ='Operating CF'!I$15 -> 56.07819 | W8: ='Operating CF'!J$15 -> 58.64831 | X8: ='Operating CF'!K$15 -> 61.295535 | Y8: ='Operating CF'!L$15 -> 64.022176 | Z8: ='Operating CF'!M$15 -> 66.830616 | AA8: ='Operating CF'!N$15 -> 69.72331 | AB8: ='Operating CF'!O$15+(('Operating CF'!O$18*D35/E$34)*(1-Assumptions!$F$24)-Assumptions!$F$20) -> 2318.2416
R9: =-Assumptions!$F$10 -> -450 | S9: ='Operating CF'!F$15 -> 48.808317 | T9: ='Operating CF'!G$15 -> 51.160342 | U9: ='Operating CF'!H$15 -> 53.582927 | V9: ='Operating CF'!I$15 -> 56.07819 | W9: ='Operating CF'!J$15 -> 58.64831 | X9: ='Operating CF'!K$15 -> 61.295535 | Y9: ='Operating CF'!L$15 -> 64.022176 | Z9: ='Operating CF'!M$15 -> 66.830616 | AA9: ='Operating CF'!N$15 -> 69.72331 | AB9: ='Operating CF'!O$15+(('Operating CF'!O$18*D35/F$34)*(1-Assumptions!$F$24)-Assumptions!$F$20) -> 1999.515
C10: X | D10: KEY EXIT / RISK FLAGS | R10: =-Assumptions!$F$10 -> -450 | S10: ='Operating CF'!F$15 -> 48.808317 | T10: ='Operating CF'!G$15 -> 51.160342 | U10: ='Operating CF'!H$15 -> 53.582927 | V10: ='Operating CF'!I$15 -> 56.07819 | W10: ='Operating CF'!J$15 -> 58.64831 | X10: ='Operating CF'!K$15 -> 61.295535 | Y10: ='Operating CF'!L$15 -> 64.022176 | Z10: ='Operating CF'!M$15 -> 66.830616 | AA10: ='Operating CF'!N$15 -> 69.72331 | AB10: ='Operating CF'!O$15+(('Operating CF'!O$18*D35/G$34)*(1-Assumptions!$F$24)-Assumptions!$F$20) -> 1744.5338
D11: Base All-in Equity XIRR | E11: ='Operating CF'!E35 -> 0.15724347 | F11: Base Exit Value | G11: ='Operating CF'!O20 -> 2341.4254 | H11: Exit Cap | I11: =Assumptions!F23 -> 0.045 | J11: Lease Term | K11: =Assumptions!F25 -> 10 | L11: Rollover Risk | M11: HIGH | R11: =-Assumptions!$F$10 -> -450 | S11: ='Operating CF'!F$15 -> 48.808317 | T11: ='Operating CF'!G$15 -> 51.160342 | U11: ='Operating CF'!H$15 -> 53.582927 | V11: ='Operating CF'!I$15 -> 56.07819 | W11: ='Operating CF'!J$15 -> 58.64831 | X11: ='Operating CF'!K$15 -> 61.295535 | Y11: ='Operating CF'!L$15 -> 64.022176 | Z11: ='Operating CF'!M$15 -> 66.830616 | AA11: ='Operating CF'!N$15 -> 69.72331 | AB11: ='Operating CF'!O$15+(('Operating CF'!O$18*D35/H$34)*(1-Assumptions!$F$24)-Assumptions!$F$20) -> 1535.9128
D12: Y1 NOI | E12: =Assumptions!F18 -> 78.400817 | F12: Senior Loan | G12: =Assumptions!F20 -> 623 | H12: Y1 DSCR | I12: =Assumptions!F18/(Assumptions!F20*Assumptions!F21) -> 2.6493475 | J12: Refi LTV | K12: =Assumptions!F20/(Assumptions!F18/Assumptions!F23) -> 0.35758556 | L12: Exit CF Share | M12: ='Operating CF'!O23/SUM('Operating CF'!F25:O25) -> 0.73764653 | R12: =-Assumptions!$F$10 -> -450 | S12: ='Operating CF'!F$15 -> 48.808317 | T12: ='Operating CF'!G$15 -> 51.160342 | U12: ='Operating CF'!H$15 -> 53.582927 | V12: ='Operating CF'!I$15 -> 56.07819 | W12: ='Operating CF'!J$15 -> 58.64831 | X12: ='Operating CF'!K$15 -> 61.295535 | Y12: ='Operating CF'!L$15 -> 64.022176 | Z12: ='Operating CF'!M$15 -> 66.830616 | AA12: ='Operating CF'!N$15 -> 69.72331 | AB12: ='Operating CF'!O$15+(('Operating CF'!O$18*D35/I$34)*(1-Assumptions!$F$24)-Assumptions!$F$20) -> 1362.062
R13: =-Assumptions!$F$10 -> -450 | S13: ='Operating CF'!F$15 -> 48.808317 | T13: ='Operating CF'!G$15 -> 51.160342 | U13: ='Operating CF'!H$15 -> 53.582927 | V13: ='Operating CF'!I$15 -> 56.07819 | W13: ='Operating CF'!J$15 -> 58.64831 | X13: ='Operating CF'!K$15 -> 61.295535 | Y13: ='Operating CF'!L$15 -> 64.022176 | Z13: ='Operating CF'!M$15 -> 66.830616 | AA13: ='Operating CF'!N$15 -> 69.72331 | AB13: ='Operating CF'!O$15+(('Operating CF'!O$18*D36/E$34)*(1-Assumptions!$F$24)-Assumptions!$F$20) -> 2057.4653
R14: =-Assumptions!$F$10 -> -450 | S14: ='Operating CF'!F$15 -> 48.808317 | T14: ='Operating CF'!G$15 -> 51.160342 | U14: ='Operating CF'!H$15 -> 53.582927 | V14: ='Operating CF'!I$15 -> 56.07819 | W14: ='Operating CF'!J$15 -> 58.64831 | X14: ='Operating CF'!K$15 -> 61.295535 | Y14: ='Operating CF'!L$15 -> 64.022176 | Z14: ='Operating CF'!M$15 -> 66.830616 | AA14: ='Operating CF'!N$15 -> 69.72331 | AB14: ='Operating CF'!O$15+(('Operating CF'!O$18*D36/F$34)*(1-Assumptions!$F$24)-Assumptions!$F$20) -> 1767.7139
C15: X | D15: BASE / DOWNSIDE / STRESS SCENARIO ANALYSIS | R15: =-Assumptions!$F$10 -> -450 | S15: ='Operating CF'!F$15 -> 48.808317 | T15: ='Operating CF'!G$15 -> 51.160342 | U15: ='Operating CF'!H$15 -> 53.582927 | V15: ='Operating CF'!I$15 -> 56.07819 | W15: ='Operating CF'!J$15 -> 58.64831 | X15: ='Operating CF'!K$15 -> 61.295535 | Y15: ='Operating CF'!L$15 -> 64.022176 | Z15: ='Operating CF'!M$15 -> 66.830616 | AA15: ='Operating CF'!N$15 -> 69.72331 | AB15: ='Operating CF'!O$15+(('Operating CF'!O$18*D36/G$34)*(1-Assumptions!$F$24)-Assumptions!$F$20) -> 1535.9128
D16: Metric | E16: Unit | F16: Base | G16: Downside | H16: Stress | I16: Modeling Logic | R16: =-Assumptions!$F$10 -> -450 | S16: ='Operating CF'!F$15 -> 48.808317 | T16: ='Operating CF'!G$15 -> 51.160342 | U16: ='Operating CF'!H$15 -> 53.582927 | V16: ='Operating CF'!I$15 -> 56.07819 | W16: ='Operating CF'!J$15 -> 58.64831 | X16: ='Operating CF'!K$15 -> 61.295535 | Y16: ='Operating CF'!L$15 -> 64.022176 | Z16: ='Operating CF'!M$15 -> 66.830616 | AA16: ='Operating CF'!N$15 -> 69.72331 | AB16: ='Operating CF'!O$15+(('Operating CF'!O$18*D36/H$34)*(1-Assumptions!$F$24)-Assumptions!$F$20) -> 1346.2573
D17: Exit Cap Rate | E17: % | F17: 0.045 | G17: 0.05 | H17: 0.055 | I17: Terminal Value = 재계약 조정 Forward NOI ÷ Exit Cap Rate | R17: =-Assumptions!$F$10 -> -450 | S17: ='Operating CF'!F$15 -> 48.808317 | T17: ='Operating CF'!G$15 -> 51.160342 | U17: ='Operating CF'!H$15 -> 53.582927 | V17: ='Operating CF'!I$15 -> 56.07819 | W17: ='Operating CF'!J$15 -> 58.64831 | X17: ='Operating CF'!K$15 -> 61.295535 | Y17: ='Operating CF'!L$15 -> 64.022176 | Z17: ='Operating CF'!M$15 -> 66.830616 | AA17: ='Operating CF'!N$15 -> 69.72331 | AB17: ='Operating CF'!O$15+(('Operating CF'!O$18*D36/I$34)*(1-Assumptions!$F$24)-Assumptions!$F$20) -> 1188.2111
D18: Renewal NOI Factor | E18: % | F18: 1 | G18: 0.9 | H18: 0.8 | I18: 임대차 만기 및 재임대 리스크를 반영해 Y11 Forward NOI에 할인율 적용 | R18: =-Assumptions!$F$10 -> -450 | S18: ='Operating CF'!F$15 -> 48.808317 | T18: ='Operating CF'!G$15 -> 51.160342 | U18: ='Operating CF'!H$15 -> 53.582927 | V18: ='Operating CF'!I$15 -> 56.07819 | W18: ='Operating CF'!J$15 -> 58.64831 | X18: ='Operating CF'!K$15 -> 61.295535 | Y18: ='Operating CF'!L$15 -> 64.022176 | Z18: ='Operating CF'!M$15 -> 66.830616 | AA18: ='Operating CF'!N$15 -> 69.72331 | AB18: ='Operating CF'!O$15+(('Operating CF'!O$18*D37/E$34)*(1-Assumptions!$F$24)-Assumptions!$F$20) -> 1796.6891
D19: Sale Cost | E19: % | F19: 0.01 | G19: 0.015 | H19: 0.02 | I19: 자산 매각 시 거래비용 차감 | R19: =-Assumptions!$F$10 -> -450 | S19: ='Operating CF'!F$15 -> 48.808317 | T19: ='Operating CF'!G$15 -> 51.160342 | U19: ='Operating CF'!H$15 -> 53.582927 | V19: ='Operating CF'!I$15 -> 56.07819 | W19: ='Operating CF'!J$15 -> 58.64831 | X19: ='Operating CF'!K$15 -> 61.295535 | Y19: ='Operating CF'!L$15 -> 64.022176 | Z19: ='Operating CF'!M$15 -> 66.830616 | AA19: ='Operating CF'!N$15 -> 69.72331 | AB19: ='Operating CF'!O$15+(('Operating CF'!O$18*D37/F$34)*(1-Assumptions!$F$24)-Assumptions!$F$20) -> 1535.9128
D20: Stabilized Loan Rate | E20: % | F20: 0.0475 | G20: 0.0525 | H20: 0.0575 | I20: 금리 및 리파이낸싱 스트레스 반영; 대출 원금은 Base Case의 623억원으로 유지 | R20: =-Assumptions!$F$10 -> -450 | S20: ='Operating CF'!F$15 -> 48.808317 | T20: ='Operating CF'!G$15 -> 51.160342 | U20: ='Operating CF'!H$15 -> 53.582927 | V20: ='Operating CF'!I$15 -> 56.07819 | W20: ='Operating CF'!J$15 -> 58.64831 | X20: ='Operating CF'!K$15 -> 61.295535 | Y20: ='Operating CF'!L$15 -> 64.022176 | Z20: ='Operating CF'!M$15 -> 66.830616 | AA20: ='Operating CF'!N$15 -> 69.72331 | AB20: ='Operating CF'!O$15+(('Operating CF'!O$18*D37/G$34)*(1-Assumptions!$F$24)-Assumptions!$F$20) -> 1327.2918
D21: Construction Cost Overrun | E21: % | F21: 0 | G21: 0.05 | H21: 0.1 | I21: 공사비 초과분은 추가 Equity 투입으로 조달한다고 가정 | R21: =-Assumptions!$F$10 -> -450 | S21: ='Operating CF'!F$15 -> 48.808317 | T21: ='Operating CF'!G$15 -> 51.160342 | U21: ='Operating CF'!H$15 -> 53.582927 | V21: ='Operating CF'!I$15 -> 56.07819 | W21: ='Operating CF'!J$15 -> 58.64831 | X21: ='Operating CF'!K$15 -> 61.295535 | Y21: ='Operating CF'!L$15 -> 64.022176 | Z21: ='Operating CF'!M$15 -> 66.830616 | AA21: ='Operating CF'!N$15 -> 69.72331 | AB21: ='Operating CF'!O$15+(('Operating CF'!O$18*D37/H$34)*(1-Assumptions!$F$24)-Assumptions!$F$20) -> 1156.6019
D22: Completion Delay | E22: months | F22: 0 | G22: 6 | H22: 12 | I22: 공사 지연기간만큼 운영 배당 시점이 후행 | R22: =-Assumptions!$F$10 -> -450 | S22: ='Operating CF'!F$15 -> 48.808317 | T22: ='Operating CF'!G$15 -> 51.160342 | U22: ='Operating CF'!H$15 -> 53.582927 | V22: ='Operating CF'!I$15 -> 56.07819 | W22: ='Operating CF'!J$15 -> 58.64831 | X22: ='Operating CF'!K$15 -> 61.295535 | Y22: ='Operating CF'!L$15 -> 64.022176 | Z22: ='Operating CF'!M$15 -> 66.830616 | AA22: ='Operating CF'!N$15 -> 69.72331 | AB22: ='Operating CF'!O$15+(('Operating CF'!O$18*D37/I$34)*(1-Assumptions!$F$24)-Assumptions!$F$20) -> 1014.3603
D23: Incremental Delay Carry | E23: 억원 | F23: =Assumptions!$F$20*Assumptions!$F$13*F22/12 -> 0 | G23: =Assumptions!$F$20*Assumptions!$F$13*G22/12 -> 17.91125 | H23: =Assumptions!$F$20*Assumptions!$F$13*H22/12 -> 35.8225 | I23: 전체 Senior PF 잔액 × PF 금리 × 지연기간을 적용한 보수적 추가 금융비용 추정치 | R23: =-Assumptions!$F$10 -> -450 | S23: ='Operating CF'!F$15 -> 48.808317 | T23: ='Operating CF'!G$15 -> 51.160342 | U23: ='Operating CF'!H$15 -> 53.582927 | V23: ='Operating CF'!I$15 -> 56.07819 | W23: ='Operating CF'!J$15 -> 58.64831 | X23: ='Operating CF'!K$15 -> 61.295535 | Y23: ='Operating CF'!L$15 -> 64.022176 | Z23: ='Operating CF'!M$15 -> 66.830616 | AA23: ='Operating CF'!N$15 -> 69.72331 | AB23: ='Operating CF'!O$15+(('Operating CF'!O$18*D38/E$34)*(1-Assumptions!$F$24)-Assumptions!$F$20) -> 1535.9128
D24: Total Equity Required | E24: 억원 | F24: =Assumptions!$F$10+Assumptions!$F$5*F21+F23 -> 450 | G24: =Assumptions!$F$10+Assumptions!$F$5*G21+G23 -> 521.56125 | H24: =Assumptions!$F$10+Assumptions!$F$5*H21+H23 -> 593.1225 | I24: 기존 Equity + 공사비 초과분 + 지연에 따른 추가 Carry 비용 | R24: =-Assumptions!$F$10 -> -450 | S24: ='Operating CF'!F$15 -> 48.808317 | T24: ='Operating CF'!G$15 -> 51.160342 | U24: ='Operating CF'!H$15 -> 53.582927 | V24: ='Operating CF'!I$15 -> 56.07819 | W24: ='Operating CF'!J$15 -> 58.64831 | X24: ='Operating CF'!K$15 -> 61.295535 | Y24: ='Operating CF'!L$15 -> 64.022176 | Z24: ='Operating CF'!M$15 -> 66.830616 | AA24: ='Operating CF'!N$15 -> 69.72331 | AB24: ='Operating CF'!O$15+(('Operating CF'!O$18*D38/F$34)*(1-Assumptions!$F$24)-Assumptions!$F$20) -> 1304.1117
D25: Forward NOI at Exit | E25: 억원 | F25: ='Operating CF'!$O$18*F18 -> 105.36414 | G25: ='Operating CF'!$O$18*G18 -> 94.827728 | H25: ='Operating CF'!$O$18*H18 -> 84.291314 | I25: 재계약 / 재임대 결과를 반영해 조정한 Y11 Forward NOI | R25: =-Assumptions!$F$10 -> -450 | S25: ='Operating CF'!F$15 -> 48.808317 | T25: ='Operating CF'!G$15 -> 51.160342 | U25: ='Operating CF'!H$15 -> 53.582927 | V25: ='Operating CF'!I$15 -> 56.07819 | W25: ='Operating CF'!J$15 -> 58.64831 | X25: ='Operating CF'!K$15 -> 61.295535 | Y25: ='Operating CF'!L$15 -> 64.022176 | Z25: ='Operating CF'!M$15 -> 66.830616 | AA25: ='Operating CF'!N$15 -> 69.72331 | AB25: ='Operating CF'!O$15+(('Operating CF'!O$18*D38/G$34)*(1-Assumptions!$F$24)-Assumptions!$F$20) -> 1118.6708
D26: Gross Exit Value | E26: 억원 | F26: =F25/F17 -> 2341.4254 | G26: =G25/G17 -> 1896.5546 | H26: =H25/H17 -> 1532.5693 | I26: 재계약 조정 Forward NOI에 시나리오별 Exit Cap Rate를 적용해 자산가치 산출 | R26: =-Assumptions!$F$10 -> -450 | S26: ='Operating CF'!F$15 -> 48.808317 | T26: ='Operating CF'!G$15 -> 51.160342 | U26: ='Operating CF'!H$15 -> 53.582927 | V26: ='Operating CF'!I$15 -> 56.07819 | W26: ='Operating CF'!J$15 -> 58.64831 | X26: ='Operating CF'!K$15 -> 61.295535 | Y26: ='Operating CF'!L$15 -> 64.022176 | Z26: ='Operating CF'!M$15 -> 66.830616 | AA26: ='Operating CF'!N$15 -> 69.72331 | AB26: ='Operating CF'!O$15+(('Operating CF'!O$18*D38/H$34)*(1-Assumptions!$F$24)-Assumptions!$F$20) -> 966.94643
D27: Net Sale Proceeds | E27: 억원 | F27: =F26*(1-F19)-Assumptions!$F$20 -> 1695.0111 | G27: =G26*(1-G19)-Assumptions!$F$20 -> 1245.1062 | H27: =H26*(1-H19)-Assumptions!$F$20 -> 878.91796 | I27: Gross Exit Value에서 매각비용과 Senior Debt 상환액을 차감 | R27: =-Assumptions!$F$10 -> -450 | S27: ='Operating CF'!F$15 -> 48.808317 | T27: ='Operating CF'!G$15 -> 51.160342 | U27: ='Operating CF'!H$15 -> 53.582927 | V27: ='Operating CF'!I$15 -> 56.07819 | W27: ='Operating CF'!J$15 -> 58.64831 | X27: ='Operating CF'!K$15 -> 61.295535 | Y27: ='Operating CF'!L$15 -> 64.022176 | Z27: ='Operating CF'!M$15 -> 66.830616 | AA27: ='Operating CF'!N$15 -> 69.72331 | AB27: ='Operating CF'!O$15+(('Operating CF'!O$18*D38/I$34)*(1-Assumptions!$F$24)-Assumptions!$F$20) -> 840.50946
D28: All-in Equity XIRR | E28: % | F28: =XIRR(E55:O55,E54:O54) -> 0.15724347 | G28: =XIRR(E57:O57,E56:O56) -> 0.11390141 | H28: =XIRR(E59:O59,E58:O58) -> 0.07600148 | I28: 개발기간 Equity 투입, 지연된 운영 배당, 시나리오별 Exit Proceeds를 모두 포함 | R28: =-Assumptions!$F$10 -> -450 | S28: ='Operating CF'!F$15 -> 48.808317 | T28: ='Operating CF'!G$15 -> 51.160342 | U28: ='Operating CF'!H$15 -> 53.582927 | V28: ='Operating CF'!I$15 -> 56.07819 | W28: ='Operating CF'!J$15 -> 58.64831 | X28: ='Operating CF'!K$15 -> 61.295535 | Y28: ='Operating CF'!L$15 -> 64.022176 | Z28: ='Operating CF'!M$15 -> 66.830616 | AA28: ='Operating CF'!N$15 -> 69.72331 | AB28: ='Operating CF'!O$15+(('Operating CF'!O$18*D39/E$34)*(1-Assumptions!$F$24)-Assumptions!$F$20) -> 1275.1365
D29: Equity MOIC | E29: x | F29: =SUM(F55:O55)/ABS(E55) -> 5.1063636 | G29: =SUM(F57:O57)/ABS(E57) -> 3.4834044 | H29: =SUM(F59:O59)/ABS(E59) -> 2.3932163 | I29: 총 양(+)의 Equity Cash Flow ÷ 총 모델상 Equity 필요액 | R29: =-Assumptions!$F$10 -> -450 | S29: ='Operating CF'!F$15 -> 48.808317 | T29: ='Operating CF'!G$15 -> 51.160342 | U29: ='Operating CF'!H$15 -> 53.582927 | V29: ='Operating CF'!I$15 -> 56.07819 | W29: ='Operating CF'!J$15 -> 58.64831 | X29: ='Operating CF'!K$15 -> 61.295535 | Y29: ='Operating CF'!L$15 -> 64.022176 | Z29: ='Operating CF'!M$15 -> 66.830616 | AA29: ='Operating CF'!N$15 -> 69.72331 | AB29: ='Operating CF'!O$15+(('Operating CF'!O$18*D39/F$34)*(1-Assumptions!$F$24)-Assumptions!$F$20) -> 1072.3106
D30: Y1 DSCR | E30: x | F30: =Assumptions!$F$18/(Assumptions!$F$20*F20) -> 2.6493475 | G30: =Assumptions!$F$18/(Assumptions!$F$20*G20) -> 2.3970287 | H30: =Assumptions!$F$18/(Assumptions!$F$20*H20) -> 2.1885914 | I30: NOI ÷ 현금이자; Base Model에서는 원금상환률 0% 유지 | R30: =-Assumptions!$F$10 -> -450 | S30: ='Operating CF'!F$15 -> 48.808317 | T30: ='Operating CF'!G$15 -> 51.160342 | U30: ='Operating CF'!H$15 -> 53.582927 | V30: ='Operating CF'!I$15 -> 56.07819 | W30: ='Operating CF'!J$15 -> 58.64831 | X30: ='Operating CF'!K$15 -> 61.295535 | Y30: ='Operating CF'!L$15 -> 64.022176 | Z30: ='Operating CF'!M$15 -> 66.830616 | AA30: ='Operating CF'!N$15 -> 69.72331 | AB30: ='Operating CF'!O$15+(('Operating CF'!O$18*D39/G$34)*(1-Assumptions!$F$24)-Assumptions!$F$20) -> 910.0498
R31: =-Assumptions!$F$10 -> -450 | S31: ='Operating CF'!F$15 -> 48.808317 | T31: ='Operating CF'!G$15 -> 51.160342 | U31: ='Operating CF'!H$15 -> 53.582927 | V31: ='Operating CF'!I$15 -> 56.07819 | W31: ='Operating CF'!J$15 -> 58.64831 | X31: ='Operating CF'!K$15 -> 61.295535 | Y31: ='Operating CF'!L$15 -> 64.022176 | Z31: ='Operating CF'!M$15 -> 66.830616 | AA31: ='Operating CF'!N$15 -> 69.72331 | AB31: ='Operating CF'!O$15+(('Operating CF'!O$18*D39/H$34)*(1-Assumptions!$F$24)-Assumptions!$F$20) -> 777.29098
R32: =-Assumptions!$F$10 -> -450 | S32: ='Operating CF'!F$15 -> 48.808317 | T32: ='Operating CF'!G$15 -> 51.160342 | U32: ='Operating CF'!H$15 -> 53.582927 | V32: ='Operating CF'!I$15 -> 56.07819 | W32: ='Operating CF'!J$15 -> 58.64831 | X32: ='Operating CF'!K$15 -> 61.295535 | Y32: ='Operating CF'!L$15 -> 64.022176 | Z32: ='Operating CF'!M$15 -> 66.830616 | AA32: ='Operating CF'!N$15 -> 69.72331 | AB32: ='Operating CF'!O$15+(('Operating CF'!O$18*D39/I$34)*(1-Assumptions!$F$24)-Assumptions!$F$20) -> 666.65863
C33: X | D33: ALL-IN EQUITY XIRR SENSITIVITY – EXIT CAP × RENEWAL NOI
D34: Renewal NOI / Exit Cap | E34: 0.04 | F34: 0.045 | G34: 0.05 | H34: 0.055 | I34: 0.06
D35: 1.1 | E35: =XIRR(R8:AB8,$R$2:$AB$2) -> 0.1759869 | F35: =XIRR(R9:AB9,$R$2:$AB$2) -> 0.16561462 | G35: =XIRR(R10:AB10,$R$2:$AB$2) -> 0.15636154 | H35: =XIRR(R11:AB11,$R$2:$AB$2) -> 0.14800177 | I35: =XIRR(R12:AB12,$R$2:$AB$2) -> 0.14037016
D36: 1 | E36: =XIRR(R13:AB13,$R$2:$AB$2) -> 0.16759092 | F36: =XIRR(R14:AB14,$R$2:$AB$2) -> 0.15724347 | G36: =XIRR(R15:AB15,$R$2:$AB$2) -> 0.14800177 | H36: =XIRR(R16:AB16,$R$2:$AB$2) -> 0.13964199 | I36: =XIRR(R17:AB17,$R$2:$AB$2) -> 0.13200048
D37: 0.9 | E37: =XIRR(R18:AB18,$R$2:$AB$2) -> 0.15833375 | F37: =XIRR(R19:AB19,$R$2:$AB$2) -> 0.14800177 | G37: =XIRR(R20:AB20,$R$2:$AB$2) -> 0.13876001 | H37: =XIRR(R21:AB21,$R$2:$AB$2) -> 0.13038689 | I37: =XIRR(R22:AB22,$R$2:$AB$2) -> 0.12272037
D38: 0.8 | E38: =XIRR(R23:AB23,$R$2:$AB$2) -> 0.14800177 | F38: =XIRR(R24:AB24,$R$2:$AB$2) -> 0.13766966 | G38: =XIRR(R25:AB25,$R$2:$AB$2) -> 0.12840936 | H38: =XIRR(R26:AB26,$R$2:$AB$2) -> 0.12000168 | I38: =XIRR(R27:AB27,$R$2:$AB$2) -> 0.11228622
D39: 0.7 | E39: =XIRR(R28:AB28,$R$2:$AB$2) -> 0.13628705 | F39: =XIRR(R29:AB29,$R$2:$AB$2) -> 0.12592807 | G39: =XIRR(R30:AB30,$R$2:$AB$2) -> 0.11661809 | H39: =XIRR(R31:AB31,$R$2:$AB$2) -> 0.1081404 | I39: =XIRR(R32:AB32,$R$2:$AB$2) -> 0.10033628
C42: X | D42: KEY RISK REGISTER & UNDERWRITING RESPONSE
D43: Risk Category | E43: Modeled? | F43: Base Exposure | G43: Downside Mechanism | H43: Impact | I43: Mitigation / Underwriting Response
...

Sheet Dev PF
C1: X | D1: Development PF Draw & Capitalized Interest Schedule (억원)
D3: Period | E3: Closing | F3: 2026Q4 | G3: 2027Q1 | H3: 2027Q2 | I3: 2027Q3 | J3: 2027Q4 | K3: 2028Q1 | L3: 2028Q2 | M3: 2028Q3 | N3: 2028Q4 | O3: 2029Q1 | P3: 2029Q2 | Q3: Total
D4: Date | E4: 46296 | F4: 46387 | G4: 46477 | H4: 46568 | I4: 46660 | J4: 46752 | K4: 46843 | L4: 46934 | M4: 47026 | N4: 47118 | O4: 47208 | P4: 47299
D6: Non-land Cost Draw % | E6: 0 | F6: 0.03 | G6: 0.05 | H6: 0.07 | I6: 0.1 | J6: 0.12 | K6: 0.14 | L6: 0.14 | M6: 0.12 | N6: 0.1 | O6: 0.08 | P6: 0.05 | Q6: =SUM(F6:P6) -> 1
D7: Non-land Development Cost | E7: 0 | F7: =(Assumptions!$F$7+Assumptions!$F$8)*F6 -> 12.867 | G7: =(Assumptions!$F$7+Assumptions!$F$8)*G6 -> 21.445 | H7: =(Assumptions!$F$7+Assumptions!$F$8)*H6 -> 30.023 | I7: =(Assumptions!$F$7+Assumptions!$F$8)*I6 -> 42.89 | J7: =(Assumptions!$F$7+Assumptions!$F$8)*J6 -> 51.468 | K7: =(Assumptions!$F$7+Assumptions!$F$8)*K6 -> 60.046 | L7: =(Assumptions!$F$7+Assumptions!$F$8)*L6 -> 60.046 | M7: =(Assumptions!$F$7+Assumptions!$F$8)*M6 -> 51.468 | ... P7: =(Assumptions!$F$7+Assumptions!$F$8)*P6 -> 21.445 | Q7: =SUM(E7:P7) -> 428.9
D8: Land Cost | E8: =Assumptions!$F$6 -> 580 | F8: 0 | G8: 0 | H8: 0 | I8: 0 | J8: 0 | K8: 0 | L8: 0 | M8: 0 | N8: 0 | O8: 0 | P8: 0 | Q8: =SUM(E8:P8) -> 580
D9: Financing Fee | E9: =Assumptions!$F$14 -> 7.7742228 | F9: 0 | G9: 0 | H9: 0 | I9: 0 | J9: 0 | K9: 0 | L9: 0 | M9: 0 | N9: 0 | O9: 0 | P9: 0 | Q9: =SUM(E9:P9) -> 7.7742228
D11: Beginning PF Balance | E11: 0 | F11: =E14 -> 137.77422 | G11: =F14 -> 152.71421 | H11: =G14 -> 176.50861 | I11: =H14 -> 209.28471 | J11: =I14 -> 255.49145 | K11: =J14 -> 311.00207 | L11: =K14 -> 375.9503 | M11: =L14 -> 441.83217 | ... P11: =O14 -> 592.87824 | Q11: 0
D12: Initial / Incremental PF Draw | E12: =Assumptions!$F$12+Assumptions!$F$14 -> 137.77422 | F12: =F7 -> 12.867 | G12: =G7 -> 21.445 | H12: =H7 -> 30.023 | I12: =I7 -> 42.89 | J12: =J7 -> 51.468 | K12: =K7 -> 60.046 | L12: =L7 -> 60.046 | M12: =M7 -> 51.468 | ... P12: =P7 -> 21.445 | Q12: =SUM(E12:P12) -> 566.67422
D13: Capitalized PF Interest | E13: 0 | F13: =(F11+0.5*F12)*Assumptions!$F$13/4 -> 2.072986 | G13: =(G11+0.5*G12)*Assumptions!$F$13/4 -> 2.3494027 | H13: =(H11+0.5*H12)*Assumptions!$F$13/4 -> 2.7531016 | I13: =(I11+0.5*I12)*Assumptions!$F$13/4 -> 3.3167396 | J13: =(J11+0.5*J12)*Assumptions!$F$13/4 -> 4.0426159 | K13: =(K11+0.5*K12)*Assumptions!$F$13/4 -> 4.9022354 | L13: =(L11+0.5*L12)*Assumptions!$F$13/4 -> 5.8358662 | M13: =(M11+0.5*M12)*Assumptions!$F$13/4 -> 6.7212637 | ... P13: =(P11+0.5*P12)*Assumptions!$F$13/4 -> 8.6767606 | Q13: =SUM(E13:P13) -> 56.325777
D14: Ending PF Balance | E14: =E11+E12+E13 -> 137.77422 | F14: =F11+F12+F13 -> 152.71421 | G14: =G11+G12+G13 -> 176.50861 | H14: =H11+H12+H13 -> 209.28471 | I14: =I11+I12+I13 -> 255.49145 | J14: =J11+J12+J13 -> 311.00207 | K14: =K11+K12+K13 -> 375.9503 | L14: =L11+L12+L13 -> 441.83217 | ... P14: =P11+P12+P13 -> 623 | Q14: =P14 -> 623
D16: Equity Draw | E16: =Assumptions!$F$10 -> 450 | F16: 0 | G16: 0 | H16: 0 | I16: 0 | J16: 0 | K16: 0 | L16: 0 | M16: 0 | N16: 0 | O16: 0 | P16: 0 | Q16: =SUM(E16:P16) -> 450
D17: Total Sources | E17: =SUM(E12,E13,E16) -> 587.77422 | F17: =SUM(F12,F13,F16) -> 14.939986 | G17: =SUM(G12,G13,G16) -> 23.794403 | H17: =SUM(H12,H13,H16) -> 32.776102 | I17: =SUM(I12,I13,I16) -> 46.20674 | J17: =SUM(J12,J13,J16) -> 55.510616 | K17: =SUM(K12,K13,K16) -> 64.948235 | L17: =SUM(L12,L13,L16) -> 65.881866 | ... P17: =SUM(P12,P13,P16) -> 30.121761 | Q17: =SUM(E17:P17) -> 1073
D18: Total Uses | E18: =SUM(E7:E9,E13) -> 587.77422 | F18: =SUM(F7:F9,F13) -> 14.939986 | G18: =SUM(G7:G9,G13) -> 23.794403 | H18: =SUM(H7:H9,H13) -> 32.776102 | I18: =SUM(I7:I9,I13) -> 46.20674 | J18: =SUM(J7:J9,J13) -> 55.510616 | K18: =SUM(K7:K9,K13) -> 64.948235 | L18: =SUM(L7:L9,L13) -> 65.881866 | ... P18: =SUM(P7:P9,P13) -> 30.121761 | Q18: =SUM(E18:P18) -> 1073
D19: Sources - Uses Check | E19: =E17-E18 -> 0 | F19: =F17-F18 -> 0 | G19: =G17-G18 -> 0 | H19: =H17-H18 -> 0 | I19: =I17-I18 -> 0 | J19: =J17-J18 -> 0 | K19: =K17-K18 -> 0 | L19: =L17-L18 -> 0 | ... P19: =P17-P18 -> 0 | Q19: =SUM(E19:P19) -> 0
C21: X | D21: PF RECONCILIATION
D22: Metric | E22: Value
D23: Final Development PF Balance | E23: =P14 -> 623
D24: Capitalized Interest | E24: =SUM(F13:P13) -> 56.325777
D25: Financing Fee | E25: =Assumptions!$F$14 -> 7.7742228
D26: Financing & Other Total | E26: =SUM(E24:E25) -> 64.1

Sheet Assumptions Reason >>>

Sheet Total Development Cost
C1: X | D1: Total Development Cost Build-Up (만원)
D3: Overview
D4: Floor | E4: 구분 | F4: 평
D5: 12F | E5: Office | F5: 151
D6: 11F | E6: Office | F6: 241
D7: 10F | E7: Office | F7: 241
D8: 9F | E8: Office | F8: 241
D9: 8F | E9: Retail | F9: 241
D10: 7F | E10: Retail | F10: 241
D11: 6F | E11: Retail | F11: 241
D12: 5F | E12: Retail | F12: 232
D13: 4F | E13: Retail | F13: 324
D14: 3F | E14: Retail | F14: 324
D15: 2F | E15: Retail | F15: 305
D16: 1F | E16: Retail | F16: 176
C19: X | D19: TOTAL DEVELOPMENT COST SUMMARY
D20: Metric | E20: 항목 | F20: Low | G20: Base | H20: High | I20: Unit | J20: Basis / Source
D21: Land Cost | E21: 토지비 | F21: =F42 -> 5800000 | G21: =G42 -> 5800000 | H21: =H42 -> 5800000 | I21: 만원 | J21: 토지 매입비
D22: Construction Cost | E22: 공사비 | F22: =F38 -> 2870600 | G22: =G38 -> 3270600 | H22: =H38 -> 3670600 | I22: 만원 | J22: Office + Retail 공사비
D23: Other Development Costs | E23: 기타 개발비 | F23: =F63 -> 1118090.1 | G23: =G63 -> 1190170.1 | H23: =H63 -> 1262250.1 | I23: 만원 | J23: 금융비용 포함 기타 개발비
D24: Total Development Cost | E24: 총 사업비 | F24: =SUM(F21:F23) -> 9788690.1 | G24: =SUM(G21:G23) -> 10260770 | H24: =SUM(H21:H23) -> 10732850 | I24: 만원 | J24: Land + Construction + Other
D25: Total Development Cost | E25: 총 사업비 (억원) | F25: =F24/10000 -> 978.86901 | G25: =G24/10000 -> 1026.077 | H25: =H24/10000 -> 1073.285 | I25: 억원 | J25: 표시 단위 변환
D27: Model Note | E27: ="공사 기간 32개월(약 2년 10개월) 기준. 기존 모델의 산식과 비용 항목을 유지하면서 Low / Base / High를 세로형 Build-Up으로 재배치." -> 공사 기간 32개월(약 2년 10개월) 기준. 기존 모델의 산식과 비용 항목을 유지하면서 Low / Base / High를 세로형 Build-Up으로 재배치.
C30: X | D30: CONSTRUCTION COST BUILD-UP
D31: Metric | E31: 항목 | F31: Low | G31: Base | H31: High | I31: Unit | J31: Basis / Source
D32: Office Area | E32: 오피스 연면적 | F32: =SUM(F5:F8) -> 874 | G32: =F32 -> 874 | H32: =F32 -> 874 | I32: 평 | J32: 기존 모델 면적
D33: Retail Area | E33: 리테일 연면적 | F33: =SUM(F9:F16) -> 2084 | G33: =F33 -> 2084 | H33: =G33 -> 2084 | I33: 평 | J33: 기존 모델 면적
D34: Office Unit Construction Cost | E34: 오피스 평당 공사비 | F34: 900 | G34: 1000 | H34: 1100 | I34: 만원/평 | J34: Peer benchmark
D35: Retail Unit Construction Cost | E35: 리테일 평당 공사비 | F35: 1000 | G35: 1150 | H35: 1300 | I35: 만원/평 | J35: Peer benchmark
D36: Office Construction Cost | E36: 오피스 공사비 | F36: =F32*F34 -> 786600 | G36: =G32*G34 -> 874000 | H36: =H32*H34 -> 961400 | I36: 만원 | J36: Area × Unit Cost
D37: Retail Construction Cost | E37: 리테일 공사비 | F37: =F33*F35 -> 2084000 | G37: =G33*G35 -> 2396600 | H37: =H33*H35 -> 2709200 | I37: 만원 | J37: Area × Unit Cost
D38: Total Construction Cost | E38: 총 공사비 | F38: =SUM(F36:F37) -> 2870600 | G38: =SUM(G36:G37) -> 3270600 | H38: =SUM(H36:H37) -> 3670600 | I38: 만원 | J38: Office + Retail
C40: X | D40: DEVELOPMENT COST ASSUMPTIONS
D41: Metric | E41: 항목 | F41: Low | G41: Base | H41: High | I41: Unit | J41: Basis / Source
D42: Land Cost | E42: 토지 매입비 | F42: 5800000 | G42: =F42 -> 5800000 | H42: =G42 -> 5800000 | I42: 만원 | J42: 기존 토지 매입비
D43: Design Fee | E43: 설계비 | F43: 0.03 | G43: =F43 -> 0.03 | H43: =G43 -> 0.03 | I43: % | J43: 공사비의 2~4% / Base 3.0%
D44: Supervision Fee | E44: 감리비 | F44: 0.015 | G44: =F44 -> 0.015 | H44: =G44 -> 0.015 | I44: % | J44: 공사비의 1~2% / Base 1.5%
D45: Design + Supervision | E45: 설계 + 감리 | F45: 0.045 | G45: =F45 -> 0.045 | H45: =G45 -> 0.045 | I45: % | J45: 공사비의 3~6% / Base 4.5%
D46: Tenant Improvement | E46: TI (Tenant Improvement) | F46: 300000 | G46: =F46 -> 300000 | H46: =G46 -> 300000 | I46: 만원 | J46: 계약금액 30억 원
D47: Financing Cost | E47: 금융비용 | F47: 0.06 | G47: =F47 -> 0.06 | H47: =G47 -> 0.06 | I47: % | J47: 기존 모델 Base 6.0%
...

Sheet Exit Value Reason
C1: X | D1: Summary
D2: Peer 거래를 통한 Exit Value 보조 추정
D3: Exit Value 2,341억의 현재 가치(2026년) 환산은 878 ~ 1,114억으로 추정되며, 이때의 평당 거래 금액은 2971 ~ 3769만원으로 Most Relevant Case와 유사
D6: Discount Rate | E6: 2039 Exit Value | F6: 2026 Present Value (억원) | G6: 평당 거래 금액 (만원)
D7: 0.06 | E7: 2,341억 | F7: 1114 | G7: =F7/$E$22*10000 -> 3769.8816
D8: 0.07 | E8: 2,341억 | F8: 988 | G8: =F8/$E$22*10000 -> 3343.4856
D9: 0.08 | E9: 2,341억 | F9: 878 | G9: =F9/$E$22*10000 -> 2971.2352
D10: 0.09 | E10: 2,341억 | F10: 780 | G10: =F10/$E$22*10000 -> 2639.5939
D11: 0.1 | E11: 2,341억 | F11: 695 | G11: =F11/$E$22*10000 -> 2351.9459
D13: 2026년도 기준
D14: Average (With Outlier) | F14: =AVERAGE(J30:J45,J47) -> 10019.686
D15: Average (Without Outlier) | F15: =AVERAGE(J30:J36,J38,J40:J44,J47) -> 7899.2489
D16: Median (With Outlier) | F16: =MEDIAN(J30:J45,J47) -> 8963.964
D17: Median (Without Outlier) | F17: =MEDIAN(J30:J36,J38,J40:J44,J47) -> 7605.7616
C19: X | D19: Peer Transaction Value Summary
D20: 2026년도 기준
D22: 연면적(평) | E22: 2955
D24: Most Relevant Case 기반 가치 산정 | G24: Average 기반 가치 산정 | J24: Median 기반 가치 산정
D25: 적용 평당 거래 금액 | E25: =J47 -> 3640 | G25: 적용 평당 거래 금액 | H25: =F15 -> 7899.2489 | J25: 적용 평당 거래 금액 | K25: =F17 -> 7605.7616
E26: =E25*E22/10000 -> 1075.62 | H26: =E22*H25/10000 -> 2334.2281 | K26: =E22*K25 -> 22475025
C28: X | D28: Exit Value Reasoning
D29: 거래 시기 | E29: 도로명 | F29: 거래 금액 | G29: 연면적(평) | H29: 용도 | I29: 출처 | J29: 평당 거래 금액 | K29: 비고
D30: 2026.07 | E30: 뚝섬로 | F30: 127 | G30: 247.2 | H30: 제1종 근생 | I30: 국토교통부 실거래가 공개시스템 | J30: =F30*10000/G30 -> 5137.5405
D31: 2026.07 | E31: 성수이로10길 | F31: 50 | G31: 39.9 | H31: 제2종 근생 | I31: 국토교통부 실거래가 공개시스템 | J31: =F31*10000/G31 -> 12531.328
D32: 2026.06 | E32: 연무장13길 | F32: 385 | G32: 610.3 | H32: 상업용 | I32: 국토교통부 실거래가 공개시스템 | J32: =F32*10000/G32 -> 6308.3729
D33: 2026.06 | E33: 광나루로 | F33: 108 | G33: 178 | H33: 제2종 근생 | I33: 국토교통부 실거래가 공개시스템 | J33: =F33*10000/G33 -> 6067.4157
D34: 2026.06 | E34: 광나루로4가길 | F34: 95 | G34: 185.5 | H34: 제2종 근생 | I34: 국토교통부 실거래가 공개시스템 | J34: =F34*10000/G34 -> 5121.2938
D35: 2026.06 | E35: 아차산로17길 | F35: 49.9 | G35: 112.6 | H35: 제1종 근생 | I35: 국토교통부 실거래가 공개시스템 | J35: =F35*10000/G35 -> 4431.6163
D36: 2026.06 | E36: 뚝섬로9길 | F36: 34 | G36: 35.3 | H36: 제2종 근생 | I36: 국토교통부 실거래가 공개시스템 | J36: =F36*10000/G36 -> 9631.728
D37: 2026.06 | E37: 연무장길 | F37: 51.3 | G37: 35.5 | H37: 제2종 근생 | I37: 국토교통부 실거래가 공개시스템 | J37: =F37*10000/G37 -> 14450.704
D38: 2026.03 | E38: 연무장길 | F38: 149 | G38: 150.4 | H38: 제2종 근생 | I38: 국토교통부 실거래가 공개시스템 | J38: =F38*10000/G38 -> 9906.9149
D39: 2026.03 | E39: 연무장길 | F39: 123 | G39: 75 | H39: 제1종 근생 | I39: 국토교통부 실거래가 공개시스템 | J39: =F39*10000/G39 -> 16400
D40: 2026.03 | E40: 아차산로17길 | F40: 73 | G40: 95.7 | H40: 제2종 근생 | I40: 국토교통부 실거래가 공개시스템 | J40: =F40*10000/G40 -> 7628.0042
D41: 2026.03 | E41: 성수일로10길 | F41: 59.7 | G41: 66.6 | H41: 제2종 근생 | I41: 국토교통부 실거래가 공개시스템 | J41: =F41*10000/G41 -> 8963.964
... D45: 2026.01 | E45: 연무장길 | F45: 57.5 | G45: 19.9 | H45: 제2종 근생 | I45: 국토교통부 실거래가 공개시스템 | J45: =F45*10000/G45 -> 28894.472
D47: 2026.02 | F47: 3276 | G47: 9000 | I47: https://en.sedaily.com/finance/2026/02/26/mastern-investment-exits-seongsu-office-deal-with-40 | J47: 3640 | K47: Most Relevant Peer

Sheet 임대료 (NOI 산출) >>>

Sheet 임대료 Summary
A1: SEONGSU E4 | RENT BENCHMARK DASHBOARD
D2: 성수동은 팝업스토어와 플래그십 스토어 수요가 강해 리테일 임대료가 일반 오피스보다 높게 형성되는 시장
D3: 일반 리테일·오피스 임대료는 높은 수준으로 언급되며, 팝업 공간에는 추가 프리미엄이 붙는 사례가 존재.
D5: Monthly Base Rent 65,334만원 기준 NOI 산출
D6: NOI | E6: =12*G18 -> 784008.17
C9: X | D9: OFFICE RENT BENCHMARK | 만원/평·월 | I9: RETAIL RENT BENCHMARK | 만원/평·월
D10: Avg excl. K2 | E10: Avg no outlier | F10: Median | G10: Most relevant | I10: Avg excl. low outlier | J10: Median | K10: Core 2 avg | L10: Most relevant
D11: ='Peer Comps'!F23 -> 18.866667 | E11: ='Peer Comps'!F24 -> 20.428571 | F11: ='Peer Comps'!F25 -> 18.9 | G11: ='Peer Comps'!F26 -> 22.9 | I11: ='Peer Comps'!F27 -> 25.533333 | J11: ='Peer Comps'!F28 -> 26.3 | K11: ='Peer Comps'!F29 -> 26.65 | L11: ='Peer Comps'!F30 -> 27
C14: X | D14: ILLUSTRATIVE BASE RENT ROLL | I14: Benchmark | J14: Rent / py
D15: Metric | E15: Office | F15: Retail | G15: Total | I15: Office Avg excl. K2 | J15: ='Peer Comps'!F23 -> 18.866667
D16: Base Rent / py | E16: ='Target Rent'!E6 -> 20.428571 | F16: ='Target Rent'!E7 -> 26.3 | I16: Office Avg no outlier | J16: ='Peer Comps'!F24 -> 20.428571
D17: Target Area (py) | E17: =SUMIF('Target Rent'!D14:D24,"Office",'Target Rent'!F14:F24) -> 1446 | F17: =SUMIF('Target Rent'!D14:D24,"Retail",'Target Rent'!F14:F24) -> 1361 | G17: =E17+F17 -> 2807 | I17: Office Median | J17: ='Peer Comps'!F25 -> 18.9
D18: Monthly Base Rent (만원) | E18: =SUMIF('Target Rent'!D14:D24,"Office",'Target Rent'!H14:H24) -> 29539.714 | F18: =SUMIF('Target Rent'!D14:D24,"Retail",'Target Rent'!H14:H24) -> 35794.3 | G18: =E18+F18 -> 65334.014 | I18: Office Most relevant | J18: ='Peer Comps'!F26 -> 22.9
D19: Monthly Mgmt. Fee (만원) | E19: =SUMIF('Target Rent'!D14:D24,"Office",'Target Rent'!J14:J24) -> 10555.8 | F19: =SUMIF('Target Rent'!D14:D24,"Retail",'Target Rent'!J14:J24) -> 2221.8325 | G19: =E19+F19 -> 12777.632 | I19: Retail Avg excl. low | J19: ='Peer Comps'!F27 -> 25.533333
D20: Monthly Occupancy Cost (만원) | E20: =E18+E19 -> 40095.514 | F20: =F18+F19 -> 38016.133 | G20: =E20+F20 -> 78111.647 | I20: Retail Median | J20: ='Peer Comps'!F28 -> 26.3
I21: Retail Core 2 avg | J21: ='Peer Comps'!F29 -> 26.65
I22: Retail Most relevant | J22: ='Peer Comps'!F30 -> 27
D23: Model note | Default Base assumptions are illustrative for visualization only. They remain fully editable and are not a source-derived investment recommendation.

Sheet Methodology
A1: METHODOLOGY & SOURCE NOTES
C3: X | D3: Source-Derived Market Summary
D4: Market Observation | E4: 성수동은 팝업스토어와 플래그십 스토어 수요가 강해 리테일 임대료가 일반 오피스보다 높게 형성되는 것으로 정리됨.
D5: Office Benchmark | E5: Office peer set includes MUSINSA S1, Bomun 243, Nexus One, Corner 19, Baekyoung Seongsu Center and K2 Seongsu.
D6: Retail Benchmark | E6: Retail peer set includes Seongsu 2-ga near MUSINSA/Gentle Monster, Yeonmujang-gil and Seongsu Station retail examples.
D7: Outlier Handling | E7: Source summary excludes the K2 legacy-discount office case from the primary office average and excludes the low-rent Yeonmujang entry case from the primary retail average.
D8: Modeling Convention | E8: Blue/yellow = editable assumption; black = formula; green = cross-sheet link; zeros shown as '-'.
C11: X | D11: Reference URLs
D12: Type | E12: Reference | F12: URL
D13: Office | E13: 무신사 성수 S1 12층 | F13: https://www.bluepinrealty.co.kr/properties/3743
D14: Office | E14: 무신사 성수 S1 7층 | F14: https://www.bluepinrealty.co.kr/properties/3744
D15: Office | E15: 보문243빌딩 7층 | F15: https://realmir.co.kr/item/view/65830
D16: Office | E16: 넥서스원 2층·3층 | F16: https://drawingoffice.co.kr/building/1848
D17: Office | E17: 넥서스원 2층·3층 | F17: https://drawingoffice.co.kr/building/1848
D18: Office | E18: 코너19 3층·4층 | F18: https://drawingoffice.co.kr/building/441
D19: Office | E19: 코너19 3층·4층 | F19: https://drawingoffice.co.kr/building/441
D20: Office | E20: 백영성수센터 3층·12층 | F20: https://drawingoffice.co.kr/building/2100
D21: Office | E21: 백영성수센터 3층·12층 | F21: https://drawingoffice.co.kr/building/2100
D22: Office | E22: ALL ABOUT K2 성수사거리점 5층 | F22: https://www.bluepinrealty.co.kr/properties/3863
D23: Retail | E23: 성수동2가 1층, 14.8평 | F23: https://realty.daangn.com/articles/4103051
... D26: Retail | E26: 연무장길 초입 1층, 약 17평 | F26: https://realty.daangn.com/articles/3495796

Sheet Peer Comps
A1: SEONGSU RENTAL PEER BENCHMARK
D2: Office / Retail asking rent peer set from the user-provided research table
C4: X | D4: Type | E4: Location / Floor | F4: Area (py) | G4: Deposit (억원) | H4: Monthly Rent (만원) | I4: Guarantee (mo.) | J4: Mgmt. Fee (만원) | K4: Rent / py (만원/평·월) | L4: Mgmt. / py (만원/평·월) | M4: Relevance | N4: Reference | O4: Source URL
D5: Office | E5: 무신사 성수 S1 12F | F5: 242.53 | G5: 6.68 | H5: 5565 | I5: 12 | J5: 1771 | K5: 22.9 | L5: 7.3 | M5: 최우선 | N5: 무신사 성수 S1 12층 | O5: https://www.bluepinrealty.co.kr/properties/3743
D6: Office | E6: 무신사 성수 S1 7F | F6: 240.54 | G6: 6.62 | H6: 5519 | I6: 11.99 | J6: 1756 | K6: 22.9 | L6: 7.3 | M6: 최우선 | N6: 무신사 성수 S1 7층 | O6: https://www.bluepinrealty.co.kr/properties/3744
D7: Office | E7: 보문243빌딩 7F | F7: 321.04 | G7: 6.49 | H7: 6080 | I7: 10.67 | J7: 1110 | K7: 18.9 | L7: 3.46 | M7: 우수 | N7: 보문243빌딩 7층 | O7: https://realmir.co.kr/item/view/65830
D8: Office | E8: 넥서스원 2F | F8: 156.36 | G8: 3.21 | H8: 3211 | I8: 10 | K8: 20.5 | M8: 우수 | N8: 넥서스원 2층·3층 | O8: https://drawingoffice.co.kr/building/1848
D9: Office | E9: 넥서스원 3F | F9: 107.9 | G9: 2.22 | H9: 2216 | I9: 10.02 | K9: 20.5 | M9: 우수 | N9: 넥서스원 2층·3층 | O9: https://drawingoffice.co.kr/building/1848
D10: Office | E10: 코너19 3F | F10: 62.34 | G10: 1.17 | H10: 1173 | I10: 9.97 | K10: 18.8 | M10: 보조 | N10: 코너19 3층·4층 | O10: https://drawingoffice.co.kr/building/441
D11: Office | E11: 코너19 4F | F11: 63.79 | G11: 1.18 | H11: 1179 | I11: 10.01 | K11: 18.5 | M11: 보조 | N11: 코너19 3층·4층 | O11: https://drawingoffice.co.kr/building/441
D12: Office | E12: 백영성수센터 12F | F12: 73.5 | G12: 0.98 | H12: 985 | I12: 9.95 | K12: 13.4 | M12: 보조 | N12: 백영성수센터 3층·12층 | O12: https://drawingoffice.co.kr/building/2100
D13: Office | E13: 백영성수센터 3F | F13: 59 | G13: 0.79 | K13: 13.4 | M13: 보조 | N13: 백영성수센터 3층·12층 | O13: https://drawingoffice.co.kr/building/2100
D14: Office | E14: K2 성수사거리점 5F | F14: 180 | G14: 2 | H14: 1690 | I14: 11.83 | J14: 189 | K14: 9.4 | L14: 1.05 | M14: 구형 할인 사례 | N14: ALL ABOUT K2 성수사거리점 5층 | O14: https://www.bluepinrealty.co.kr/properties/3863
D15: Retail | E15: 성수동2가, 무신사·젠틀몬스터 인근 1F | F15: 14.8 | G15: 0.5 | H15: 400 | I15: 12.5 | J15: 20 | K15: 27 | L15: 1.35 | N15: 성수동2가 1층, 14.8평 | O15: https://realty.daangn.com/articles/4103051
D16: Retail | E16: 연무장길, 성수역 3·4번 출구 1F | F16: 16 | G16: 0.5 | H16: 420 | I16: 11.9 | J16: 15 | K16: 26.3 | L16: 0.94 | N16: 연무장길 1층, 16평 | O16: https://realty.daangn.com/articles/4118688
D17: Retail | E17: 성수역 오피스빌딩 1F | F17: 15 | G17: 0.3 | H17: 350 | I17: 8.57 | J17: 30 | K17: 23.3 | L17: 2 | N17: 성수역 오피스빌딩 1층, 15평 | O17: https://realty.daangn.com/articles/4061429
D18: Retail | E18: 연무장길 초입 1F | F18: 17 | G18: 0.3 | H18: 190 | I18: 15.79 | J18: 38 | K18: 11.2 | L18: 2.24 | N18: 연무장길 초입 1층, 약 17평 | O18: https://realty.daangn.com/articles/3495796
C21: X | D21: BENCHMARK CALCULATIONS
D22: Benchmark | E22: Formula / Definition | F22: Rent / py | G22: Mgmt. / py
D23: Office Avg (excl. K2 legacy discount) | E23: AVERAGE of Office rows 5:13 | F23: =AVERAGE(K5:K13) -> 18.866667 | G23: =AVERAGE(L5:L7) -> 6.02
D24: Office Avg (excl. K2 + Baekyoung lower-end comps) | E24: AVERAGE of Office rows 5:11 | F24: =AVERAGE(K5:K11) -> 20.428571 | G24: =AVERAGE(L5:L7) -> 6.02
D25: Office Median (excl. K2) | E25: MEDIAN of Office rows 5:13 | F25: =MEDIAN(K5:K13) -> 18.9 | G25: =MEDIAN(L5:L7) -> 7.3
D26: Office Most Relevant Peer | E26: MUSINSA Seongsu S1 asking rent | F26: =AVERAGE(K5:K6) -> 22.9 | G26: =AVERAGE(L5:L6) -> 7.3
D27: Retail Avg (excl. low outlier) | E27: AVERAGE of Retail rows 15:17 | F27: =AVERAGE(K15:K17) -> 25.533333 | G27: =AVERAGE(L15:L17) -> 1.43
D28: Retail Median (excl. low outlier) | E28: MEDIAN of Retail rows 15:17 | F28: =MEDIAN(K15:K17) -> 26.3 | G28: =MEDIAN(L15:L17) -> 1.35
D29: Retail Core 2 Peer Avg | E29: AVERAGE of two most location-relevant Retail peers | F29: =AVERAGE(K15:K16) -> 26.65 | G29: =AVERAGE(L15:L16) -> 1.145
D30: Retail Most Relevant Peer | E30: Seongsu 2-ga near MUSINSA / Gentle Monster | F30: =K15 -> 27 | G30: =L15 -> 1.35

Sheet Target Rent
A1: E4 TARGET RENT CALCULATION
D2: Illustrative floor-by-floor rent roll using editable benchmark assumptions. Blue/yellow cells are editable model inputs.
C4: X | D4: MODEL ASSUMPTIONS (Editable)
D5: Assumption | E5: Value | F5: Unit | G5: Source / Rationale
D6: Office Base Rent | E6: ='Peer Comps'!F24 -> 20.428571 | F6: 만원/평·월 | G6: Default = Office Avg excluding K2 + lower-end Baekyoung comps
D7: Retail Base Rent | E7: ='Peer Comps'!F28 -> 26.3 | F7: 만원/평·월 | G7: Default = Retail median excluding low outlier
D8: Office Mgmt. Fee | E8: ='Peer Comps'!G26 -> 7.3 | F8: 만원/평·월 | G8: Default = most relevant MUSINSA S1 peer average
D9: Retail Mgmt. Fee | E9: =AVERAGE('Peer Comps'!L15:L18) -> 1.6325 | F9: 만원/평·월 | G9: Default = average of known retail management-fee peers
C12: X | D12: FLOOR-BY-FLOOR TARGET RENT ROLL
D13: Type | E13: Floor | F13: Area (py) | G13: Base Rent / py | H13: Monthly Base Rent (만원) | I13: Mgmt. / py | J13: Monthly Mgmt. Fee (만원) | K13: Monthly Occupancy Cost (만원)
D14: Office | E14: 12F | F14: 241 | G14: =$E$6 -> 20.428571 | H14: =F14*G14 -> 4923.2857 | I14: =$E$8 -> 7.3 | J14: =F14*I14 -> 1759.3 | K14: =H14+J14 -> 6682.5857
D15: Office | E15: 10F | F15: 241 | G15: =$E$6 -> 20.428571 | H15: =F15*G15 -> 4923.2857 | I15: =$E$8 -> 7.3 | J15: =F15*I15 -> 1759.3 | K15: =H15+J15 -> 6682.5857
D16: Office | E16: 9F | F16: 241 | G16: =$E$6 -> 20.428571 | H16: =F16*G16 -> 4923.2857 | I16: =$E$8 -> 7.3 | J16: =F16*I16 -> 1759.3 | K16: =H16+J16 -> 6682.5857
D17: Office | E17: 8F | F17: 241 | G17: =$E$6 -> 20.428571 | H17: =F17*G17 -> 4923.2857 | I17: =$E$8 -> 7.3 | J17: =F17*I17 -> 1759.3 | K17: =H17+J17 -> 6682.5857
D18: Office | E18: 7F | F18: 241 | G18: =$E$6 -> 20.428571 | H18: =F18*G18 -> 4923.2857 | I18: =$E$8 -> 7.3 | J18: =F18*I18 -> 1759.3 | K18: =H18+J18 -> 6682.5857
D19: Office | E19: 6F | F19: 241 | G19: =$E$6 -> 20.428571 | H19: =F19*G19 -> 4923.2857 | I19: =$E$8 -> 7.3 | J19: =F19*I19 -> 1759.3 | K19: =H19+J19 -> 6682.5857
D20: Retail | E20: 5F | F20: 232 | G20: =$E$7 -> 26.3 | H20: =F20*G20 -> 6101.6 | I20: =$E$9 -> 1.6325 | J20: =F20*I20 -> 378.74 | K20: =H20+J20 -> 6480.34
D21: Retail | E21: 4F | F21: 324 | G21: =$E$7 -> 26.3 | H21: =F21*G21 -> 8521.2 | I21: =$E$9 -> 1.6325 | J21: =F21*I21 -> 528.93 | K21: =H21+J21 -> 9050.13
D22: Retail | E22: 3F | F22: 324 | G22: =$E$7 -> 26.3 | H22: =F22*G22 -> 8521.2 | I22: =$E$9 -> 1.6325 | J22: =F22*I22 -> 528.93 | K22: =H22+J22 -> 9050.13
D23: Retail | E23: 2F | F23: 305 | G23: =$E$7 -> 26.3 | H23: =F23*G23 -> 8021.5 | I23: =$E$9 -> 1.6325 | J23: =F23*I23 -> 497.9125 | K23: =H23+J23 -> 8519.4125
D24: Retail | E24: 1F | F24: 176 | G24: =$E$7 -> 26.3 | H24: =F24*G24 -> 4628.8 | I24: =$E$9 -> 1.6325 | J24: =F24*I24 -> 287.32 | K24: =H24+J24 -> 4916.12
D26: TOTAL | H26: =SUM(H14:H24) -> 65334.014 | J26: =SUM(J14:J24) -> 12777.632 | K26: =SUM(K14:K24) -> 78111.647
C29: X | D29: OFFICE BENCHMARK SENSITIVITY | 241 py Standard Floor
D30: Scenario | E30: Rent / py | F30: Monthly Rent (만원)
D31: Average (excl. K2) | E31: ='Peer Comps'!F23 -> 18.866667 | F31: =241*E31 -> 4546.8667
D32: Average (No Outlier) | E32: ='Peer Comps'!F24 -> 20.428571 | F32: =241*E32 -> 4923.2857
D33: Median | E33: ='Peer Comps'!F25 -> 18.9 | F33: =241*E33 -> 4554.9
D34: Most Relevant Peer | E34: ='Peer Comps'!F26 -> 22.9 | F34: =241*E34 -> 5518.9

Sheet Raw Data >>>
