Workbook

Sheet README (2)
A1: README | Retail Income 추정 모델
C3: 모델 구조 · 시트 구성 · 검토 가이드
C4: 1~4층 팝업·갤러리·카페 + 5~8층 고정매장 매출을 공개 Peer와 운영 가정을 바탕으로 추정한 Retail Gross Sales Proxy 모델
B5: X | C5: 01 | 핵심 결과
D6: 1~8층 연간 총 매출 Proxy | G6: ='[1]Income Summary'!P15 -> 1299.2037 | K6: 억원 / 년
D7: 1~4층 팝업·갤러리·카페 | G7: =SUM('[1]Income Summary'!P6:P9) -> 963.4011 | K7: 억원 / 년
D8: 5~8층 고정매장 / 전문 운영사 | G8: =SUM('[1]Income Summary'!P10:P13) -> 335.80257 | K8: 억원 / 년
B10: X | C10: 02 | 시트 구성
D11: Income Summary | G11: 1~8층 층별 구성, 매출 추정치 및 전체 합계를 한눈에 확인하는 요약 시트
D12: 1F Income ~ 4F Income | G12: 팝업 브랜드 A/B/C, 4층 Gallery·Café의 단위 매출과 연간 회전수를 이용한 층별 매출 산출
D13: 5F Income ~ 8F Income | G13: Beauty / Women’s / Men’s / Rare & Resale의 고정매장 단위 매출을 이용한 층별 매출 산출
D14: Peer Income | G14: 카페·팝업·전시·리테일 Peer의 공개 단위 매출 자료 및 원천 Source 정리
D15: Fixed Store Peer Calc | G15: 글로벌 리테일 Peer 매출을 환율·매장면적·Store Capture·E4 Scale로 정규화한 단위 매출 산출
B17: X | C17: 03 | 산출 로직
D18: 1~3층 팝업 | G18: 브랜드 유형별 1회 Event 매출 × 연간 회전수 × Zone 수를 적용하여 연간 Gross Sales 산출
D19: 4층 복합 프로그램 | G19: 팝업 A/B/C에 Gallery·Café의 연간 단위 매출과 규모 조정치를 추가 반영
D20: 5~7층 고정매장 | G20: 공개 Peer의 매장 생산성을 E4 매장 면적에 맞춰 정규화하고 층별 Store 수를 곱해 산출
D21: 8층 Rare & Resale | G21: KOMEHYO 등 전문 리세일 Peer를 기반으로 매장 규모 및 E4 Scale을 반영해 연간 매출 추정
B23: X | C23: 04 | 해석 시 유의사항
D24: Landlord NOI 아님 | G24: 본 모델의 Income은 임차인·매장·이벤트의 Gross Sales Proxy이며, 임대료 또는 Landlord NOI와 동일하지 않음
D25: 팝업 회전수 민감도 | G25: 1~4층은 기본 연 4회 Event 운영 가정에 민감하므로 실제 운영계획에 따라 회전수를 재검토해야 함
D26: Peer 정규화 | G26: 5~8층은 해외 Peer의 매출·매장면적·온라인 매출 비중 등을 조정한 Proxy이므로 실제 입점 브랜드와 차이가 발생할 수 있음
D27: 환율 및 Scale 가정 | G27: 글로벌 Peer 환산 과정의 FX, Store Capture, E4 Scale 등 파란색 입력값은 검토 시 우선 확인 대상
B29: X | C29: 05 | 모델 사용 규칙 및 추천 검토 순서
D30: 파란색 글씨 | G30: 직접 입력하는 가정값 / 시나리오 입력값
D31: 검정색 글씨 | G31: 동일 시트 내 계산식 및 산출값
D32: 초록색 글씨 | G32: 다른 시트를 참조하는 연결 수식
D33: 추천 검토 순서 | G33: Income Summary → 각 Floor Income → Fixed Store Peer Calc → Peer Income 순으로 확인
C35: NOTE | E35: 본 모델은 Retail 운영 매출의 규모를 비교·추정하기 위한 보조 모델입니다. 사업성 평가 시에는 임대료, 수수료 구조, 운영비, 공실, Tenant Mix 및 실제 임대차 조건을 별도로 반영해야 합니다.

Sheet Floor Income >>>

Sheet Income Summary
C1: X | D1: Retail Income Summary – 1F to 8F
D2: 1F–4F = Popup / Gallery / Café gross-sales proxy | 5F–8F = Fixed-store / specialist-operator gross-sales proxy. 모든 수치는 tenant / store / event sales proxy이며 Landlord NOI 또는 임대수익과 다름.
C4: X | D4: FLOOR SUMMARY
D5: Floor | E5: Program | F5: A (#) | G5: B (#) | H5: C (#) | I5: Gallery (#) | J5: Café (#) | K5: Fixed Stores / Operator (#) | L5: A Gross Sales | M5: B Gross Sales | N5: C Gross Sales | O5: Other / Fixed Retail | P5: Floor Total | Q5: % of Total
D6: 1F | E6: Popup Discovery | F6: 1 | G6: 1 | H6: 5 | I6: 0 | J6: 0 | K6: 0 | L6: ='1F Income'!K16 -> 60 | M6: ='1F Income'!K17 -> 28 | N6: ='1F Income'!K18 -> 120 | O6: 0 | P6: ='1F Income'!K20 -> 208 | Q6: =P6/$P$15 -> 0.16009807
D7: 2F | E7: Popup Discovery / Growth | F7: 1 | G7: 2 | H7: 8 | I7: 0 | J7: 0 | K7: 0 | L7: ='2F Income'!K16 -> 60 | M7: ='2F Income'!K17 -> 56 | N7: ='2F Income'!K18 -> 192 | O7: 0 | P7: ='2F Income'!K20 -> 308 | Q7: =P7/$P$15 -> 0.2370683
D8: 3F | E8: Popup Transition | F8: 1 | G8: 2 | H8: 6 | I8: 0 | J8: 0 | K8: 0 | L8: ='3F Income'!K16 -> 60 | M8: ='3F Income'!K17 -> 56 | N8: ='3F Income'!K18 -> 144 | O8: 0 | P8: ='3F Income'!K20 -> 260 | Q8: =P8/$P$15 -> 0.20012259
D9: 4F | E9: Anchor + Gallery / Café | F9: 2 | G9: 1 | H9: 1 | I9: 1 | J9: 1 | K9: 0 | L9: ='4F Income'!K17 -> 120 | M9: ='4F Income'!K18 -> 28 | N9: ='4F Income'!K19 -> 24 | O9: =SUM('4F Income'!K20:K21) -> 15.4011 | P9: ='4F Income'!K23 -> 187.4011 | Q9: =P9/$P$15 -> 0.14424305
D10: 5F | E10: Beauty Discovery | F10: 0 | G10: 0 | H10: 0 | I10: 0 | J10: 0 | K10: 8 | L10: 0 | M10: 0 | N10: 0 | O10: ='5F Income'!K16 -> 74.397281 | P10: ='5F Income'!K20 -> 74.397281 | Q10: =P10/$P$15 -> 0.057263755
D11: 6F | E11: Women’s Fashion | F11: 0 | G11: 0 | H11: 0 | I11: 0 | J11: 0 | K11: 5 | L11: 0 | M11: 0 | N11: 0 | O11: ='6F Income'!K16 -> 85.631054 | P11: ='6F Income'!K20 -> 85.631054 | Q11: =P11/$P$15 -> 0.065910416
D12: 7F | E12: Men’s Fashion | F12: 0 | G12: 0 | H12: 0 | I12: 0 | J12: 0 | K12: 5 | L12: 0 | M12: 0 | N12: 0 | O12: ='7F Income'!K16 -> 92.492249 | P12: ='7F Income'!K20 -> 92.492249 | Q12: =P12/$P$15 -> 0.071191493
D13: 8F | E13: Rare & Resale Destination | F13: 0 | G13: 0 | H13: 0 | I13: 0 | J13: 0 | K13: 1 | L13: 0 | M13: 0 | N13: 0 | O13: ='8F Income'!K16 -> 83.281982 | P13: ='8F Income'!K20 -> 83.281982 | Q13: =P13/$P$15 -> 0.06410233
D15: TOTAL 1F–8F ESTIMATED ANNUAL GROSS SALES | P15: =SUM(P6:P13) -> 1299.2037 | Q15: =1 -> 1

Sheet 1F Income
D1: 1F Retail / Popup Income Build-Up
D2: 운영 도면 구성: A 1 / B 1 / C 5
D3: ※ Estimated Annual Gross Sales = tenant / event gross sales proxy. Landlord NOI가 아님. Popup 연간 회전수는 파란색 입력값(기본 4회/년).
D5: KEY BENCHMARK ASSUMPTIONS
D6: Metric | E6: Benchmark | F6: Unit | G6: Annualization | H6: Basis / Peer | I6: Source
D7: A | 유명 / 핫 브랜드 | E7: =MEDIAN('Peer Income'!N47:N51) -> 15 | F7: 억원 / event | G7: 4 | H7: Median: Isegye Idol / SEVENTEEN / Hello Kitty / Fu Bao / Nintendo | I7: https://www.hankyung.com/article/202406235300i
D8: B | 기존 성장 브랜드 | E8: =MEDIAN('Peer Income'!N52:N54) -> 7 | F8: 억원 / event | G8: 4 | H8: Median: Matin Kim Busan / Osaka / SATUR | I8: https://www.ktnews.com/news/articleView.html?idxno=124946
D9: C | 신생 브랜드 | E9: ='Peer Income'!N55 -> 6 | F9: 억원 / event | G9: 4 | H9: The Barnnet first Korea popup | I9: https://fashionbiz.co.kr/article/214757
D14: FLOOR INCOME BUILD-UP
D15: Zone | E15: Type | F15: Count (#) | G15: Unit Benchmark | H15: Unit | I15: Events / Yr | J15: Scale % | K15: Annual Gross Sales | L15: Share of Floor | M15: Basis
D16: A | E16: 유명 / 핫 브랜드 | F16: 1 | G16: =E7 -> 15 | H16: 억원 / event | I16: 4 | J16: 1 | K16: =F16*G16*I16*J16 -> 60 | L16: =IF($K$20=0,"",K16/$K$20) -> 0.28846154 | M16: =H7 -> Median: Isegye Idol / SEVENTEEN / Hello Kitty / Fu Bao / Nintendo
D17: B | E17: 기존 성장 브랜드 | F17: 1 | G17: =E8 -> 7 | H17: 억원 / event | I17: 4 | J17: 1 | K17: =F17*G17*I17*J17 -> 28 | L17: =IF($K$20=0,"",K17/$K$20) -> 0.13461538 | M17: =H8 -> Median: Matin Kim Busan / Osaka / SATUR
D18: C | E18: 신생 브랜드 | F18: 5 | G18: =E9 -> 6 | H18: 억원 / event | I18: 4 | J18: 1 | K18: =F18*G18*I18*J18 -> 120 | L18: =IF($K$20=0,"",K18/$K$20) -> 0.57692308 | M18: =H9 -> The Barnnet first Korea popup
D20: 1F TOTAL ESTIMATED ANNUAL GROSS SALES | K20: =SUM(K16:K18) -> 208 | L20: 1 | M20: Tenant / event gross sales proxy

Sheet 2F Income
D1: 2F Retail / Popup Income Build-Up
D2: 운영 도면 구성: A 1 / B 2 / C 8
D3: ※ Estimated Annual Gross Sales = tenant / event gross sales proxy. Landlord NOI가 아님. Popup 연간 회전수는 파란색 입력값(기본 4회/년).
D5: KEY BENCHMARK ASSUMPTIONS
D6: Metric | E6: Benchmark | F6: Unit | G6: Annualization | H6: Basis / Peer | I6: Source
D7: A | 유명 / 핫 브랜드 | E7: =MEDIAN('Peer Income'!N47:N51) -> 15 | F7: 억원 / event | G7: 4 | H7: Median: Isegye Idol / SEVENTEEN / Hello Kitty / Fu Bao / Nintendo | I7: https://www.hankyung.com/article/202406235300i
D8: B | 기존 성장 브랜드 | E8: =MEDIAN('Peer Income'!N52:N54) -> 7 | F8: 억원 / event | G8: 4 | H8: Median: Matin Kim Busan / Osaka / SATUR | I8: https://www.ktnews.com/news/articleView.html?idxno=124946
D9: C | 신생 브랜드 | E9: ='Peer Income'!N55 -> 6 | F9: 억원 / event | G9: 4 | H9: The Barnnet first Korea popup | I9: https://fashionbiz.co.kr/article/214757
D14: FLOOR INCOME BUILD-UP
D15: Zone | E15: Type | F15: Count (#) | G15: Unit Benchmark | H15: Unit | I15: Events / Yr | J15: Scale % | K15: Annual Gross Sales | L15: Share of Floor | M15: Basis
D16: A | E16: 유명 / 핫 브랜드 | F16: 1 | G16: =E7 -> 15 | H16: 억원 / event | I16: 4 | J16: 1 | K16: =F16*G16*I16*J16 -> 60 | L16: =IF($K$20=0,"",K16/$K$20) -> 0.19480519 | M16: =H7 -> Median: Isegye Idol / SEVENTEEN / Hello Kitty / Fu Bao / Nintendo
D17: B | E17: 기존 성장 브랜드 | F17: 2 | G17: =E8 -> 7 | H17: 억원 / event | I17: 4 | J17: 1 | K17: =F17*G17*I17*J17 -> 56 | L17: =IF($K$20=0,"",K17/$K$20) -> 0.18181818 | M17: =H8 -> Median: Matin Kim Busan / Osaka / SATUR
D18: C | E18: 신생 브랜드 | F18: 8 | G18: =E9 -> 6 | H18: 억원 / event | I18: 4 | J18: 1 | K18: =F18*G18*I18*J18 -> 192 | L18: =IF($K$20=0,"",K18/$K$20) -> 0.62337662 | M18: =H9 -> The Barnnet first Korea popup
D20: 2F TOTAL ESTIMATED ANNUAL GROSS SALES | K20: =SUM(K16:K18) -> 308 | L20: 1 | M20: Tenant / event gross sales proxy

Sheet 3F Income
D1: 3F Retail / Popup Income Build-Up
D2: 운영 도면 구성: A 1 / B 2 / C 6
D3: ※ Estimated Annual Gross Sales = tenant / event gross sales proxy. Landlord NOI가 아님. Popup 연간 회전수는 파란색 입력값(기본 4회/년).
D5: KEY BENCHMARK ASSUMPTIONS
D6: Metric | E6: Benchmark | F6: Unit | G6: Annualization | H6: Basis / Peer | I6: Source
D7: A | 유명 / 핫 브랜드 | E7: =MEDIAN('Peer Income'!N47:N51) -> 15 | F7: 억원 / event | G7: 4 | H7: Median: Isegye Idol / SEVENTEEN / Hello Kitty / Fu Bao / Nintendo | I7: https://www.hankyung.com/article/202406235300i
D8: B | 기존 성장 브랜드 | E8: =MEDIAN('Peer Income'!N52:N54) -> 7 | F8: 억원 / event | G8: 4 | H8: Median: Matin Kim Busan / Osaka / SATUR | I8: https://www.ktnews.com/news/articleView.html?idxno=124946
D9: C | 신생 브랜드 | E9: ='Peer Income'!N55 -> 6 | F9: 억원 / event | G9: 4 | H9: The Barnnet first Korea popup | I9: https://fashionbiz.co.kr/article/214757
D14: FLOOR INCOME BUILD-UP
D15: Zone | E15: Type | F15: Count (#) | G15: Unit Benchmark | H15: Unit | I15: Events / Yr | J15: Scale % | K15: Annual Gross Sales | L15: Share of Floor | M15: Basis
D16: A | E16: 유명 / 핫 브랜드 | F16: 1 | G16: =E7 -> 15 | H16: 억원 / event | I16: 4 | J16: 1 | K16: =F16*G16*I16*J16 -> 60 | L16: =IF($K$20=0,"",K16/$K$20) -> 0.23076923 | M16: =H7 -> Median: Isegye Idol / SEVENTEEN / Hello Kitty / Fu Bao / Nintendo
D17: B | E17: 기존 성장 브랜드 | F17: 2 | G17: =E8 -> 7 | H17: 억원 / event | I17: 4 | J17: 1 | K17: =F17*G17*I17*J17 -> 56 | L17: =IF($K$20=0,"",K17/$K$20) -> 0.21538462 | M17: =H8 -> Median: Matin Kim Busan / Osaka / SATUR
D18: C | E18: 신생 브랜드 | F18: 6 | G18: =E9 -> 6 | H18: 억원 / event | I18: 4 | J18: 1 | K18: =F18*G18*I18*J18 -> 144 | L18: =IF($K$20=0,"",K18/$K$20) -> 0.55384615 | M18: =H9 -> The Barnnet first Korea popup
D20: 3F TOTAL ESTIMATED ANNUAL GROSS SALES | K20: =SUM(K16:K18) -> 260 | L20: 1 | M20: Tenant / event gross sales proxy

Sheet 4F Income
D1: 4F Retail / Popup Income Build-Up
D2: 운영 도면 구성: A 2 / B 1 / C 1 / Gallery 1 / Café 1
D3: ※ Estimated Annual Gross Sales = tenant / event gross sales proxy. Landlord NOI가 아님. Popup 연간 회전수는 파란색 입력값(기본 4회/년).
D5: KEY BENCHMARK ASSUMPTIONS
D6: Metric | E6: Benchmark | F6: Unit | G6: Annualization | H6: Basis / Peer | I6: Source
D7: A | 유명 / 핫 브랜드 | E7: =MEDIAN('Peer Income'!N47:N51) -> 15 | F7: 억원 / event | G7: 4 | H7: Median: Isegye Idol / SEVENTEEN / Hello Kitty / Fu Bao / Nintendo | I7: https://www.hankyung.com/article/202406235300i
D8: B | 기존 성장 브랜드 | E8: =MEDIAN('Peer Income'!N52:N54) -> 7 | F8: 억원 / event | G8: 4 | H8: Median: Matin Kim Busan / Osaka / SATUR | I8: https://www.ktnews.com/news/articleView.html?idxno=124946
D9: C | 신생 브랜드 | E9: ='Peer Income'!N55 -> 6 | F9: 억원 / event | G9: 4 | H9: The Barnnet first Korea popup | I9: https://fashionbiz.co.kr/article/214757
D10: Gallery | 전시 | E10: ='Peer Income'!M59 -> 47.79 | F10: 억원 / year | G10: 0.25 | H10: Arte Museum Jeju annual venue revenue × small-gallery scale | I10: https://www.unicornfactory.co.kr/article/2023041411280462038
D11: Café | 프리미엄 카페 | E11: =MEDIAN('Peer Income'!M24,'Peer Income'!M28,'Peer Income'!M33) -> 3.4536 | F11: 억원 / store / year | G11: 1 | H11: Median: Twosome / Hollys / Dessert39 | I11: https://fchamall.com/franchise-info/%ED%88%AC%EC%8D%B8%ED%94%8C%EB%A0%88%EC%9D%B4%EC%8A%A4
D15: FLOOR INCOME BUILD-UP
D16: Zone | E16: Type | F16: Count (#) | G16: Unit Benchmark | H16: Unit | I16: Events / Yr | J16: Scale % | K16: Annual Gross Sales | L16: Share of Floor | M16: Basis
D17: A | E17: 유명 / 핫 브랜드 | F17: 2 | G17: =E7 -> 15 | H17: 억원 / event | I17: 4 | J17: 1 | K17: =F17*G17*I17*J17 -> 120 | L17: =IF($K$23=0,"",K17/$K$23) -> 0.64033776 | M17: =H7 -> Median: Isegye Idol / SEVENTEEN / Hello Kitty / Fu Bao / Nintendo
D18: B | E18: 기존 성장 브랜드 | F18: 1 | G18: =E8 -> 7 | H18: 억원 / event | I18: 4 | J18: 1 | K18: =F18*G18*I18*J18 -> 28 | L18: =IF($K$23=0,"",K18/$K$23) -> 0.14941214 | M18: =H8 -> Median: Matin Kim Busan / Osaka / SATUR
D19: C | E19: 신생 브랜드 | F19: 1 | G19: =E9 -> 6 | H19: 억원 / event | I19: 4 | J19: 1 | K19: =F19*G19*I19*J19 -> 24 | L19: =IF($K$23=0,"",K19/$K$23) -> 0.12806755 | M19: =H9 -> The Barnnet first Korea popup
D20: Gallery | E20: 전시 / 갤러리 | F20: 1 | G20: =E10 -> 47.79 | H20: 억원 / year | I20: 1 | J20: 0.25 | K20: =F20*G20*I20*J20 -> 11.9475 | L20: =IF($K$23=0,"",K20/$K$23) -> 0.063753628 | M20: Arte Museum Jeju scaled to small 4F gallery (model assumption)
D21: Café | E21: 카페 | F21: 1 | G21: =E11 -> 3.4536 | H21: 억원 / store / year | I21: 1 | J21: 1 | K21: =F21*G21*I21*J21 -> 3.4536 | L21: =IF($K$23=0,"",K21/$K$23) -> 0.018428921 | M21: Premium café peer median
D23: 4F TOTAL ESTIMATED ANNUAL GROSS SALES | K23: =SUM(K17:K21) -> 187.4011 | L23: 1 | M23: Tenant / event gross sales proxy

Sheet 5F Income
D1: 5F Beauty Discovery Floor – Fixed Store Income Build-Up
D2: 운영 구성: Beauty 고정점포 8개 | 232평 / 점포당 약 29.0평
D3: ※ Estimated Annual Gross Sales = tenant / store gross-sales proxy. Landlord NOI가 아님. 5F는 향수·스킨케어·메이크업·바디·헤어 등 8개 고정점포로 구성.
D5: KEY FIXED-STORE PEER BENCHMARKS
D6: Metric | E6: Benchmark | F6: Unit | G6: Annualization | H6: Basis / Peer | I6: Source
D7: Bath & Body Works | E7: ='Fixed Store Peer Calc'!R16 -> 15.235701 | F7: 억원 / store / year | G7: 1 | H7: Direct store productivity | I7: SEC 10-K FY2024
D8: Ulta Beauty | E8: ='Fixed Store Peer Calc'!R17 -> 9.2996601 | F8: 억원 / store / year | G8: 1 | H8: Omnichannel normalized store proxy | I8: SEC 10-K FY2024
D9: Sally Beauty | E9: ='Fixed Store Peer Calc'!R18 -> 5.1731713 | F9: 억원 / store / year | G9: 1 | H9: Segment revenue normalized store proxy | I9: FY2025 Annual Report
D10: 5F Beauty Base | E10: ='Fixed Store Peer Calc'!G29 -> 9.2996601 | F10: 억원 / store / year | G10: 1 | H10: Median of normalized beauty peers | I10: Fixed Store Peer Calc
D14: FLOOR INCOME BUILD-UP
D15: Zone | E15: Type | F15: Count (#) | G15: Unit Benchmark | H15: Unit | I15: Annualization | J15: Scale % | K15: Annual Gross Sales | L15: Share of Floor | M15: Basis
D16: Beauty | E16: Beauty fixed shops | F16: 8 | G16: ='Fixed Store Peer Calc'!G29 -> 9.2996601 | H16: 억원 / store / year | I16: 1 | J16: 1 | K16: =F16*G16*I16*J16 -> 74.397281 | L16: =K16/$K$20 -> 1 | M16: Beauty peer median | 8 fixed stores
D20: 5F TOTAL ESTIMATED ANNUAL GROSS SALES | K20: =SUM(K16:K18) -> 74.397281 | L20: =1 -> 1 | M20: Tenant / store gross-sales proxy; not Landlord NOI

Sheet 6F Income
D1: 6F Women’s Fashion – Fixed Store Income Build-Up
D2: 운영 구성: Women’s Fashion 중형 고정점포 5개 | 241평 / 점포당 약 48.2평
D3: ※ Estimated Annual Gross Sales = tenant / store gross-sales proxy. Landlord NOI가 아님. 독립적 매장 아이덴티티를 유지하는 5개 중형 여성패션 숍 구성.
D5: KEY FIXED-STORE PEER BENCHMARKS
D6: Metric | E6: Benchmark | F6: Unit | G6: Annualization | H6: Basis / Peer | I6: Source
D7: Aerie | E7: ='Fixed Store Peer Calc'!R19 -> 20.338268 | F7: 억원 / store / year | G7: 1 | H7: Brand revenue normalized store proxy | I7: AEO FY2025 Annual Report
D8: Victoria’s Secret | E8: ='Fixed Store Peer Calc'!R20 -> 13.914154 | F8: 억원 / store / year | G8: 1 | H8: 1Q2026 direct store productivity annualized | I8: SEC filing | 1Q2026
D9: 6F Women’s Base | E9: ='Fixed Store Peer Calc'!G30 -> 17.126211 | F9: 억원 / store / year | G9: 1 | H9: Median of Aerie / Victoria’s Secret proxy | I9: Fixed Store Peer Calc
D14: FLOOR INCOME BUILD-UP
D15: Zone | E15: Type | F15: Count (#) | G15: Unit Benchmark | H15: Unit | I15: Annualization | J15: Scale % | K15: Annual Gross Sales | L15: Share of Floor | M15: Basis
D16: Women’s | E16: Women’s fashion fixed shops | F16: 5 | G16: ='Fixed Store Peer Calc'!G30 -> 17.126211 | H16: 억원 / store / year | I16: 1 | J16: 1 | K16: =F16*G16*I16*J16 -> 85.631054 | L16: =K16/$K$20 -> 1 | M16: Women’s fashion peer median | 5 fixed stores
D20: 6F TOTAL ESTIMATED ANNUAL GROSS SALES | K20: =SUM(K16:K18) -> 85.631054 | L20: =1 -> 1 | M20: Tenant / store gross-sales proxy; not Landlord NOI

Sheet 7F Income
D1: 7F Men’s Fashion – Fixed Store Income Build-Up
D2: 운영 구성: Men’s Fashion 고정점포 5개 | 241평 / 점포당 약 48.2평
D3: ※ Estimated Annual Gross Sales = tenant / store gross-sales proxy. Landlord NOI가 아님. Contemporary·Street·Casual·Designer mix를 지향.
D5: KEY FIXED-STORE PEER BENCHMARKS
D6: Metric | E6: Benchmark | F6: Unit | G6: Annualization | H6: Basis / Peer | I6: Source
D7: American Eagle | E7: ='Fixed Store Peer Calc'!R21 -> 11.28517 | F7: 억원 / store / year | G7: 1 | H7: Unisex casual proxy normalized to store area | I7: AEO FY2025 Annual Report
D8: Abercrombie | E8: ='Fixed Store Peer Calc'!R22 -> 25.71173 | F8: 억원 / store / year | G8: 1 | H8: Contemporary / designer-casual proxy | I8: SEC 10-K FY2024
D9: 7F Men’s Base | E9: ='Fixed Store Peer Calc'!G31 -> 18.49845 | F9: 억원 / store / year | G9: 1 | H9: Median of normalized menswear proxies | I9: Fixed Store Peer Calc
D14: FLOOR INCOME BUILD-UP
D15: Zone | E15: Type | F15: Count (#) | G15: Unit Benchmark | H15: Unit | I15: Annualization | J15: Scale % | K15: Annual Gross Sales | L15: Share of Floor | M15: Basis
D16: Men’s | E16: Men’s fashion fixed shops | F16: 5 | G16: ='Fixed Store Peer Calc'!G31 -> 18.49845 | H16: 억원 / store / year | I16: 1 | J16: 1 | K16: =F16*G16*I16*J16 -> 92.492249 | L16: =K16/$K$20 -> 1 | M16: Men’s fashion proxy median | 5 fixed stores
D20: 7F TOTAL ESTIMATED ANNUAL GROSS SALES | K20: =SUM(K16:K18) -> 92.492249 | L20: =1 -> 1 | M20: Tenant / store gross-sales proxy; not Landlord NOI

Sheet 8F Income
D1: 8F Rare & Resale – Specialist Operator Income Build-Up
D2: 운영 구성: Rare & Resale 전문 운영사 1개 | 241평 전체 장기임차형 운영
D3: ※ Estimated Annual Gross Sales = tenant / operator gross-sales proxy. Landlord NOI가 아님. 희소 스니커즈·한정판·디자이너 아카이브 등 Destination Retail 성격.
D5: KEY FIXED-STORE PEER BENCHMARKS
D6: Metric | E6: Benchmark | F6: Unit | G6: Annualization | H6: Basis / Peer | I6: Source
D7: KOMEHYO | E7: ='Fixed Store Peer Calc'!R23 -> 77.502312 | F7: 억원 / operator / year | G7: 1 | H7: Retail-sales / sales-capable-store proxy × E4 scale | I7: KOMEHYO FY2026 Results
D8: 6F / 7F Fashion Density Cross-check | E8: =AVERAGE('Fixed Store Peer Calc'!H30,'Fixed Store Peer Calc'!H31) -> 89.061652 | F8: 억원 / floor / year | G8: 1 | H8: Average of women’s / men’s E4 floor proxies | I8: Internal cross-check
D9: 8F Rare & Resale Base | E9: ='Fixed Store Peer Calc'!G32 -> 83.281982 | F9: 억원 / operator / year | G9: 1 | H9: Blended KOMEHYO + fashion density cross-check | I9: Fixed Store Peer Calc
D10: The RealReal | E10: N/A | F10: Context only | G10: 1 | H10: Platform GMV only; excluded from store-income benchmark | I10: The RealReal IR | Context only
D14: FLOOR INCOME BUILD-UP
D15: Zone | E15: Type | F15: Count (#) | G15: Unit Benchmark | H15: Unit | I15: Annualization | J15: Scale % | K15: Annual Gross Sales | L15: Share of Floor | M15: Basis
D16: Rare & Resale | E16: Specialist resale operator | F16: 1 | G16: ='Fixed Store Peer Calc'!G32 -> 83.281982 | H16: 억원 / operator / year | I16: 1 | J16: 1 | K16: =F16*G16*I16*J16 -> 83.281982 | L16: =K16/$K$20 -> 1 | M16: KOMEHYO scaled proxy + fashion density cross-check
D20: 8F TOTAL ESTIMATED ANNUAL GROSS SALES | K20: =SUM(K16:K18) -> 83.281982 | L20: =1 -> 1 | M20: Tenant / store gross-sales proxy; not Landlord NOI

Sheet Assumptions >>>

Sheet Peer Income
A1: Peer Unit Sales Benchmark – Store / Popup / Exhibition
D2: 기업 전체 Revenue / EBITDA / 영업이익은 제외. 공개된 매장 1개 평균 매출, 실제 팝업 1건 매출, 단일 전시장/행사 단위 지표만 사용.
D3: Units: Monthly Sales = 만원 / store(or venue) / month | Annual Sales = 억원 / store(or venue) / year | Popup/Event Sales = 억원 / event | Daily Sales = 억원 / day
D4: Source convention: FTC information-disclosure based store averages = Actual Avg | reported popup/event sales = Actual Event | derived simple division = Proxy | non-revenue traffic data = Visitor Only
C6: X | D6: MODEL TAKEAWAYS – UNIT SALES ONLY
D7: Metric | E7: Value | F7: Unit | G7: Comment
D8: Café peer average monthly sales | E8: =AVERAGE(L24:L44) -> 2399.0952 | F8: 만원 / store / month | G8: 단순평균; hybrid·무인·업종평균 포함
D9: Café peer median monthly sales | E9: =MEDIAN(L24:L44) -> 1923 | F9: 만원 / store / month | G9: 극단값 영향을 줄인 중앙값
D10: Popup peer average event sales | E10: =AVERAGE(N47:N56) -> 14.3 | F10: 억원 / event | G10: 운영기간·IP 강도 차이 큼
D11: Popup peer median event sales | E11: =MEDIAN(N47:N56) -> 9.5 | F11: 억원 / event | G11: 이벤트 매출 중앙값
D12: 5F Beauty | E12: 9.3 | G12: 3 beauty peers 중앙값
D13: 6F Women’s | E13: 17.13 | G13: Aerie + Victoria’s Secret 중앙값
D14: 7F Men’s | E14: 18.5 | G14: American Eagle + Abercrombie 중앙값
D15: 8F Rare & Resale | E15: 83.28 | G15: KOMEHYO scaled peer + fashion density cross-check
C21: X | D21: Category | E21: Stage / Type | F21: Peer / Event | G21: Location | H21: Benchmark Type | I21: Disclosure Basis | J21: Reference Period | K21: Store / Venue Count (#) | L21: Avg Monthly Sales (만원 / unit / month) | M21: Avg Annual Sales (억원 / unit / year) | N21: Popup / Event Sales (억원 / event) | O21: Operating Days (#) | P21: Avg Daily Sales (억원 / day) | Q21: Annual Sales / Py (만원 / 평 / 년) | R21: Visitors (#) | S21: Revenue / Visitor (만원 / person) | T21: Data Quality | U21: Source | V21: Notes
L22: (만원 / unit / month) | M22: (억원 / unit / year) | N22: (억원 / Event) | P22: (억원 / day) | Q22: (만원 / 평 / 년) | S22: (만원 / person)
C23: X | D23: GROUP A | CAFÉ – PUBLIC STORE AVERAGE SALES
D24: Café | E24: Premium / Large-format | F24: A Twosome Place | G24: Korea | H24: Franchise store average | I24: 2025 FTC disclosure average franchise-store sales | J24: 2025 info disclosure | K24: 1510 | L24: 4764 | M24: =L24*12/10000 -> 5.7168 | Q24: 1005 | T24: Actual Avg | U24: https://fchamall.com/franchise-info/%ED%88%AC%EC%8D%B8%ED%94%8C%EB%A0%88%EC%9D%B4%EC%8A%A4 | V24: 공정위 정보공개서 기반. 대형·프리미엄 카페 peer.
D25: Café | E25: Value / High-volume | F25: Mega MGC Coffee | G25: Korea | H25: Franchise store average | I25: 2025 FTC disclosure average franchise-store sales | J25: 2025 info disclosure | K25: 3325 | L25: 3237 | M25: =L25*12/10000 -> 3.8844 | Q25: 2241 | T25: Actual Avg | U25: https://fchamall.com/franchise-info/%EB%A9%94%EA%B0%80%EC%97%A0%EC%A7%80%EC%94%A8%EC%BB%A4%ED%94%BC-mega-mgc-coffee | V25: 매장 1개 기준 평균 매출. 본사 매출과 무관.
D26: Café | E26: Value / High-volume | F26: Compose Coffee | G26: Korea | H26: Franchise store average | I26: 2025 FTC disclosure average franchise-store sales | J26: 2025 info disclosure | K26: 2649 | L26: 2266 | M26: =L26*12/10000 -> 2.7192 | Q26: 1803 | T26: Actual Avg | U26: https://fchamall.com/franchise-info/%EC%BB%B4%ED%8F%AC%EC%A6%88%EC%BB%A4%ED%94%BC-compose-coffee | V26: 매장 1개 기준 평균 매출.
D27: Café | E27: Value / High-volume | F27: Paik's Coffee | G27: Korea | H27: Franchise store average | I27: 2025 FTC disclosure average franchise-store sales | J27: 2025 info disclosure | K27: 1712 | L27: 2704 | M27: =L27*12/10000 -> 3.2448 | T27: Actual Avg | U27: https://fchamall.com/franchise-info/%EB%B9%BD%EB%8B%A4%EB%B0%A9 | V27: 매장 1개 기준 평균 매출.
D28: Café | E28: Premium / Mid-large | F28: Hollys | G28: Korea | H28: Franchise store average | I28: 2025 FTC disclosure average franchise-store sales | J28: 2025 info disclosure | K28: 402 | L28: 2878 | M28: =L28*12/10000 -> 3.4536 | Q28: 613 | T28: Actual Avg | U28: https://fchamall.com/franchise-info/%ED%95%A0%EB%A6%AC%EC%8A%A4 | V28: 좌석형·대형 매장을 포함하는 premium/mid-large peer.
D29: Café | E29: Mid-market | F29: Ediya Coffee | G29: Korea | H29: Franchise store average | I29: 2025 FTC disclosure average franchise-store sales | J29: 2025 info disclosure | K29: 2562 | L29: 1623 | M29: =L29*12/10000 -> 1.9476 | Q29: 633 | T29: Actual Avg | U29: https://fchamall.com/franchise-info/%EC%9D%B4%EB%94%94%EC%95%BC%EC%BB%A4%ED%94%BC | V29: 공정위 커피 업종 평균과 가까운 mid-market peer.
D30: Café | E30: Value / Take-out | F30: The Venti | G30: Korea | H30: Franchise store average | I30: 2025 FTC disclosure average franchise-store sales | J30: 2025 info disclosure | K30: 1230 | L30: 1845 | M30: =L30*12/10000 -> 2.214 | Q30: 1740 | T30: Actual Avg | U30: https://fchamall.com/franchise-info/%EB%8D%94%EB%B2%A4%ED%8B%B0 | V30: 테이크아웃 비중 높은 value peer.
D31: Café | E31: Specialty / Growth | F31: Ten Percent Specialty Coffee | G31: Korea | H31: Franchise store average | I31: 2025 FTC disclosure average franchise-store sales | J31: 2025 info disclosure | K31: 814 | L31: 1877 | M31: =L31*12/10000 -> 2.2524 | T31: Actual Avg | U31: https://fchamall.com/franchise-info/%ED%85%90%ED%8D%BC%EC%84%BC%ED%8A%B8%EC%8A%A4%ED%8E%98%EC%85%9C%ED%8B%B0%EC%BB%A4%ED%94%BC | V31: 2018년 가맹사업 시작. 성장형 specialty/value peer.
D32: Café | E32: Value / Office Take-out | F32: Mammoth Express | G32: Korea | H32: Franchise store average | I32: 2025 FTC disclosure average franchise-store sales | J32: 2025 info disclosure | K32: 742 | L32: 1923 | M32: =L32*12/10000 -> 2.3076 | Q32: 1842 | T32: Actual Avg | U32: https://fchamall.com/franchise-info/%EB%A7%A4%EB%A8%B8%EB%93%9C%EC%9D%B5%EC%8A%A4%ED%94%84%EB%A0%88%EC%8A%A4-mammoth-express | V32: 오피스 상권 / 소형 take-out peer.
D33: Café | E33: Dessert / Large menu | F33: Dessert39 | G33: Korea | H33: Franchise store average | I33: 2025 FTC disclosure average franchise-store sales | J33: 2025 info disclosure | K33: 504 | L33: 2053 | M33: =L33*12/10000 -> 2.4636 | Q33: 916 | T33: Actual Avg | U33: https://fchamall.com/franchise-info/%EB%94%94%EC%A0%80%ED%8A%B839 | V33: 카페+디저트 복합 peer.
D34: Café | E34: Regional / Value | F34: Cafe Bombom | G34: Korea | H34: Franchise store average | I34: 2025 FTC disclosure average franchise-store sales | J34: 2025 info disclosure | K34: 414 | L34: 1446 | M34: =L34*12/10000 -> 1.7352 | Q34: 1501 | T34: Actual Avg | U34: https://fchamall.com/franchise-info/%EC%B9%B4%ED%8E%98%EB%B4%84%EB%B4%84 | V34: 지역 기반 value peer.
D35: Café | E35: Emerging / Fast rollout | F35: Baekeok Coffee | G35: Korea | H35: Franchise store average | I35: 2025 FTC disclosure average franchise-store sales | J35: 2025 info disclosure | K35: 165 | L35: 3269 | M35: =L35*12/10000 -> 3.9228 | Q35: 2797 | T35: Actual Avg | U35: https://fchamall.com/franchise-info/%EB%B0%B1%EC%96%B5%EC%BB%A4%ED%94%BC | V35: 가맹사업 2022년 시작. 2025 정보공개서 기준 신규 77개, 폐업·해지 0개.
D36: Café | E36: Emerging / Growth | F36: PLUS 82 | G36: Korea | H36: Franchise store average | I36: 2025 FTC disclosure average franchise-store sales | J36: 2025 info disclosure | K36: 146 | L36: 3532 | M36: =L36*12/10000 -> 4.2384 | T36: Actual Avg | U36: https://fchamall.com/franchise-info/plus-82-%ED%94%8C%EB%9F%AC%EC%8A%A4-82 | V36: 가맹사업 2022년 시작. 신규/성장 브랜드의 상단 매출 peer.
D37: Café | E37: Growth / Value | F37: OOZYCOFFEE | G37: Korea | H37: Franchise store average | I37: 2025 FTC disclosure average franchise-store sales | J37: 2025 info disclosure | K37: 199 | L37: 1915 | M37: =L37*12/10000 -> 2.298 | T37: Actual Avg | U37: https://fchamall.com/franchise-info/%EC%9A%B0%EC%A7%80%EC%BB%A4%ED%94%BC-oozycoffee | V37: 가맹사업 2020년 시작. 성장형 value peer.
D38: Café | E38: Emerging / Small network | F38: Pound Coffee | G38: Korea | H38: Franchise store average | I38: 2025 FTC disclosure average franchise-store sales | J38: 2025 info disclosure | K38: 8 | L38: 2622 | M38: =L38*12/10000 -> 3.1464 | Q38: 2281 | T38: Actual Avg | U38: https://fchamall.com/franchise-info/%ED%8C%8C%EC%9A%B4%EB%93%9C%EC%BB%A4%ED%94%BC | V38: 가맹사업 2022년 시작. 표본 8개로 small-sample 주의.
D39: Café | E39: Emerging / Small network | F39: Every Coffee | G39: Korea | H39: Franchise store average | I39: 2025 FTC disclosure average franchise-store sales | J39: 2025 info disclosure | K39: 18 | L39: 1569 | M39: =L39*12/10000 -> 1.8828 | Q39: 501 | T39: Actual Avg | U39: https://fchamall.com/franchise-info/every-coffee-%EC%97%90%EB%B8%8C%EB%A6%AC%EC%BB%A4%ED%94%BC | V39: 가맹사업 2021년 시작. small-sample peer.
D40: Café | E40: Emerging / Regional | F40: Mori Coffee | G40: Korea | H40: Franchise store average | I40: 2025 FTC disclosure average franchise-store sales | J40: 2025 info disclosure | K40: 81 | L40: 1428 | M40: =L40*12/10000 -> 1.7136 | Q40: 953 | T40: Actual Avg | U40: https://fchamall.com/franchise-info/%EB%AA%A8%EB%A6%AC%EC%BB%A4%ED%94%BC | V40: 가맹사업 2020년 시작. 81개 점포 성장형 peer.
D41: Café | E41: Emerging / Unmanned | F41: Cafe Freehet | G41: Korea | H41: Franchise store average | I41: 2025 FTC disclosure average franchise-store sales | J41: 2025 info disclosure | K41: 151 | L41: 461 | M41: =L41*12/10000 -> 0.5532 | Q41: 517 | T41: Actual Avg | U41: https://fchamall.com/franchise-info/%EC%B9%B4%ED%8E%98%ED%94%84%EB%A6%AC%ED%97%B7 | V41: 가맹사업 2023년 시작. 무인/저인력 포맷의 신규 peer.
D42: Café | E42: Emerging / Unmanned | F42: Cafe Manwolgyeong | G42: Korea | H42: Franchise store average | I42: 2025 FTC disclosure average franchise-store sales | J42: 2025 info disclosure | K42: 340 | L42: 487 | M42: =L42*12/10000 -> 0.5844 | T42: Actual Avg | U42: https://fchamall.com/franchise-info/%EC%B9%B4%ED%8E%98%EB%A7%8C%EC%9B%94%EA%B2%BD | V42: 가맹사업 2021년 시작. 무인·저매출 구조 비교용.
D43: Café | E43: Cafe / Bakery hybrid | F43: Paik's Bakery Lab | G43: Korea | H43: Franchise store average | I43: 2025 FTC disclosure average franchise-store sales | J43: 2025 info disclosure | K43: 18 | L43: 6924 | M43: =L43*12/10000 -> 8.3088 | T43: Actual Avg | U43: https://fchamall.com/franchise-info/%EB%B9%BD%EB%8B%A4%EB%B0%A9%EB%B9%B5%EC%97%B0%EA%B5%AC%EC%86%8C | V43: 소수 점포·베이커리 결합형. 일반 카페보다 높은 매출 benchmark.
D44: Café | E44: Industry Benchmark | F44: Coffee franchise category average | G44: Korea | H44: Industry average | I44: 2025 FTC disclosure category benchmark | J44: 2025 info disclosure | K44: 96 | L44: 1558 | M44: =L44*12/10000 -> 1.8696 | T44: Industry Avg | U44: https://fchamall.com/rankings/franchise | V44: 활성 커피 브랜드 업종 평균 월매출 약 1,558만원.
C46: X | D46: GROUP B | POPUP / HOT & EMERGING BRAND – ACTUAL EVENT SALES
D47: Popup / Retail | E47: Viral / Digital IP | F47: Isegye Idol popup | G47: The Hyundai Seoul | H47: Actual popup sales | I47: News-reported event sales | J47: 2024 / 2 weeks | N47: 34 | O47: 14 | P47: =IF(OR(N47="",O47=""),"",N47/O47) -> 2.4285714 | T47: Actual Event | U47: https://www.hankyung.com/article/202406235300i | V47: 2주 34억원. 기사에서 동일 규모 일반 패션 매장의 일매출 약 1,000만원과 비교.
...

Sheet Fixed Store Peer Calc
D1: Fixed Store Peer Income Benchmark – Beauty / Women’s Fashion / Men’s Fashion / Rare & Resale
D2: Public peer data are normalized to E4-sized stores. Annual Gross Sales is a tenant/store sales proxy, not Landlord NOI. Omnichannel normalization and E4 scaling are explicit model assumptions.
D4: MODEL ASSUMPTIONS / NORMALIZATION
D5: Assumption | E5: Value | F5: Unit | G5: Use | H5: Source / Note
D6: USD / KRW FX | E6: 1418.31 | F6: KRW / USD | G6: USD peer conversion | H6: 플랫폼 환율 기준 | 2026-08-11
D7: JPY / KRW FX | E7: 8.91367 | F7: KRW / JPY | G7: KOMEHYO conversion | H7: 플랫폼 환율 기준 | 2026-08-11
D8: Ulta Store Capture | E8: 0.85 | F8: % of omnichannel revenue | G8: Beauty normalization | H8: 모델 가정: 이커머스 / 살롱 / 기타 매출을 반영한 할인 조정
D9: Sally Store Capture | E9: 0.893 | F9: % of segment revenue | G9: Beauty normalization | H9: 연결 기준 이커머스 매출 비중 10.7%를 적용한 추정치
D10: AEO / A&F Store Capture | E10: 0.7 | F10: % of brand revenue | G10: Fashion normalization | H10: 모델 가정: 오프라인 매장 생산성 산출 시 전체 매출의 70%만 반영
D11: KOMEHYO E4 Scale | E11: 0.8 | F11: % of avg sales-capable store | G11: Rare & Resale | H11: 모델 가정: E4는 평균적인 판매 가능 Peer 대비 매장 규모가 작고 상품 구성이 제한적임
D12: Sqft per Pyeong | E12: 35.583 | F12: sqft / py | G12: Area conversion | H12: 1평 = 3.3058㎡ = 35.583ft²
D14: PEER NORMALIZATION & E4 UNIT SALES PROXY
D15: Category | E15: Peer | F15: Benchmark Type | G15: Period | H15: Input Metric | I15: Input Unit | J15: Store Count | K15: Avg Store Area (sqft) | L15: Store Capture / Retail % | M15: FX to KRW | N15: Annual Sales / Store (억원) | O15: Annual Sales / Py (만원/평/년) | P15: E4 Unit Area (py) | Q15: E4 Scale % | R15: E4 Unit Sales Proxy (억원/년) | S15: Data Quality | T15: Source
D16: Beauty | E16: Bath & Body Works | F16: Direct store productivity | G16: FY2024 | H16: 1041 | I16: USD / sqft / year | J16: 1895 | K16: 2843 | L16: =100% -> 1 | M16: =$E$6 -> 1418.31 | N16: =H16*K16*M16/100000000 -> 41.975778 | O16: =H16*$E$12*M16/10000 -> 5253.6901 | P16: 29 | Q16: =100% -> 1 | R16: =O16*P16/10000*Q16 -> 15.235701 | S16: Actual Store Productivity | T16: https://www.sec.gov/Archives/edgar/data/701985/000070198525000011/bbwi-20250201.htm
D17: Beauty | E17: Ulta Beauty | F17: Omnichannel revenue / store area | G17: FY2024 | H17: 11295.654 | I17: USD mm / year | J17: 1445 | K17: 10457 | L17: =$E$8 -> 0.85 | M17: =$E$6 -> 1418.31 | N17: =H17*L17*M17/J17/100 -> 94.239641 | O17: =N17/(K17/$E$12)*10000 -> 3206.7793 | P17: 29 | Q17: =100% -> 1 | R17: =O17*P17/10000*Q17 -> 9.2996601 | S17: Proxy | T17: https://www.sec.gov/Archives/edgar/data/1403568/000155837025003810/ulta-20250201x10k.htm
D18: Beauty | E18: Sally Beauty | F18: Segment revenue / avg stores | G18: FY2025 | H18: 2094.363 | I18: USD mm / year | J18: 3112.5 | K18: 1700 | L18: =$E$9 -> 0.893 | M18: =$E$6 -> 1418.31 | N18: =H18*L18*M18/J18/100 -> 8.5224649 | O18: =N18/(K18/$E$12)*10000 -> 1783.8522 | P18: 29 | Q18: =100% -> 1 | R18: =O18*P18/10000*Q18 -> 5.1731713 | S18: Proxy | T18: https://www.sallybeautyholdings.com/~/media/Files/S/Sally-Beauty/annual-report/2025-annual-report.pdf
D19: Women’s Fashion | E19: Aerie | F19: Brand revenue / avg stores | G19: FY2025 | H19: 1940.924 | I19: USD mm / year | J19: 325 | K19: 5000 | L19: =$E$10 -> 0.7 | M19: =$E$6 -> 1418.31 | N19: =H19*L19*M19/J19/100 -> 59.291764 | O19: =N19/(K19/$E$12)*10000 -> 4219.5577 | P19: 48.2 | Q19: =100% -> 1 | R19: =O19*P19/10000*Q19 -> 20.338268 | S19: Proxy | T19: https://www.sec.gov/Archives/edgar/data/919012/000119312526227191/d83289dars.pdf
D20: Women’s Fashion | E20: Victoria’s Secret | F20: Direct store productivity annualized | G20: 1Q2026 | H20: 143 | I20: USD / sqft / 13 weeks | K20: 6913 | L20: =100% -> 1 | M20: =$E$6 -> 1418.31 | N20: =H20*4*K20*M20/100000000 -> 56.083325 | O20: =H20*4*$E$12*M20/10000 -> 2886.7539 | P20: 48.2 | Q20: =100% -> 1 | R20: =O20*P20/10000*Q20 -> 13.914154 | S20: Actual Store Productivity | T20: https://www.sec.gov/Archives/edgar/data/1856437/000185643726000013/vsco-20260502.htm
D21: Men’s Fashion | E21: American Eagle | F21: Brand revenue / avg stores | G21: FY2025 | H21: 3411.237 | I21: USD mm / year | J21: 817 | K21: 6300 | L21: =$E$10 -> 0.7 | M21: =$E$6 -> 1418.31 | N21: =H21*L21*M21/J21/100 -> 41.453294 | O21: =N21/(K21/$E$12)*10000 -> 2341.3215 | P21: 48.2 | Q21: =100% -> 1 | R21: =O21*P21/10000*Q21 -> 11.28517 | S21: Proxy | T21: https://www.sec.gov/Archives/edgar/data/919012/000119312526227191/d83289dars.pdf
D22: Men’s Fashion | E22: Abercrombie | F22: Brand revenue / current store area | G22: FY2024 | H22: 2556.434 | I22: USD mm / year | J22: 278 | K22: 6090 | L22: =$E$10 -> 0.7 | M22: =$E$6 -> 1418.31 | N22: =H22*L22*M22/J22/100 -> 91.297523 | O22: =N22/(K22/$E$12)*10000 -> 5334.3838 | P22: 48.2 | Q22: =100% -> 1 | R22: =O22*P22/10000*Q22 -> 25.71173 | S22: Proxy | T22: https://www.sec.gov/Archives/edgar/data/1018840/000101884025000013/anf-20250201.htm
D23: Rare & Resale | E23: KOMEHYO | F23: Retail-sales / sales-capable stores | G23: FY2026 | H23: 221707 | I23: JPY mm consolidated revenue | J23: 92 | L23: 0.451 | M23: =$E$7 -> 8.91367 | N23: =H23*L23*M23/J23/100 -> 96.87789 | P23: 241 | Q23: =$E$11 -> 0.8 | R23: =N23*Q23 -> 77.502312 | S23: Proxy | T23: https://komehyohds.com/ir/upload_file/m000-/E_setsumeishiryo20260514.pdf
D24: Rare & Resale | E24: The RealReal | F24: Platform GMV – context only | G24: FY2025 | H24: 2100 | I24: USD mm GMV / year | M24: =$E$6 -> 1418.31 | P24: 241 | S24: Context Only | T24: https://investor.therealreal.com/overview/default.aspx
D27: E4 FIXED-STORE BASE BENCHMARKS | J27: BENCHMARK INTERPRETATION
D28: Category | E28: Store Count | F28: E4 Unit Area (py) | G28: Base Unit Sales (억원/년) | H28: Floor Sales Proxy (억원/년)
D29: Beauty | E29: 8 | F29: 29 | G29: =MEDIAN(R16:R18) -> 9.2996601 | H29: =E29*G29 -> 74.397281
D30: Women’s Fashion | E30: 5 | F30: 48.2 | G30: =MEDIAN(R19:R20) -> 17.126211 | H30: =E30*G30 -> 85.631054
D31: Men’s Fashion | E31: 5 | F31: 48.2 | G31: =MEDIAN(R21:R22) -> 18.49845 | H31: =E31*G31 -> 92.492249
D32: Rare & Resale | E32: 1 | F32: 241 | G32: =AVERAGE(R23,AVERAGE(G30/F30,G31/F31)*F32) -> 83.281982 | H32: =E32*G32 -> 83.281982
